Workbook

Sheet wsList
D1: ※ 오픈된 엑셀 파일만 대상으로 선택 (선택 디폴트는 현재 파일) | L1: 나눔고딕
D2: ※ 암호 해제 조건에서 함수가 정상 동작합니다. | L2: Times New Roman
B3: fullPath | C3: C:\MyWork\evms\pilot_WBS-CA_draft_v2.xlsm | L3: 10 | M3: (미적용)
B4: 번호 | C4: 워크시트 | D4: 설명 | E4: 비고
B5: 1 | C5: wsList | D5: 내비게이션 시트
B6: 2 | C6: Encrypt | D6: 워크시트 암호 설정
B7: 3 | C7: 안내 | D7: 워크시트 기능에 대해서 요약, 설명해 주세요.
B8: 4 | C8: CA_개요 | D8: 워크시트 기능에 대해서 요약, 설명해 주세요.
B9: 5 | C9: WP_상세 | D9: 워크시트 기능에 대해서 요약, 설명해 주세요.
B10: 6 | C10: 마일스톤_요약 | D10: 워크시트 기능에 대해서 요약, 설명해 주세요.
B11: 7 | C11: LOE_계정 | D11: 워크시트 기능에 대해서 요약, 설명해 주세요.
B12: 8 | C12: 가정 | D12: 워크시트 기능에 대해서 요약, 설명해 주세요.
B13: 9 | C13: 계획곡선_후보 | D13: 워크시트 기능에 대해서 요약, 설명해 주세요.
B14: 10 | C14: 계획곡선_보정 | D14: 워크시트 기능에 대해서 요약, 설명해 주세요.
B15: 11 | C15: 실적MM_입력 | D15: 워크시트 기능에 대해서 요약, 설명해 주세요.
B16: 12 | C16: EVMS_대시보드 | D16: 워크시트 기능에 대해서 요약, 설명해 주세요.
... B20: 16 | C20: 배포게이트_체크리스트 | D20: 워크시트 기능에 대해서 요약, 설명해 주세요.

Sheet Encrypt
H2: ★ 워크시트 E:N열 암호조건을 설정하세요. (R:W열의 가이드 참조)
D3: (수기 편집 불가 열) | E3: Variant | F3: Boolean | G3: Boolean | H3: Boolean | I3: Boolean | J3: Boolean | K3: Boolean | L3: Boolean | M3: Boolean | N3: Boolean
B4: No | C4: Sheets | D4: Encrypt | E4: InputColorRGB | F4: ForceFullLock_NoException | G4: UserInterfaceOnly | H4: AllowFormatting | I4: AllowInserting | J4: AllowDeleting | K4: AllowSorting | L4: AllowFiltering | M4: LockShapes | N4: LockOLEObjects | R4: 파라미터명 | S4: 타입 | T4: 기본값 | U4: 필수여부 | V4: 기능 설명 | W4: 사용 예시
B5: 1 | C5: wsList | E5: 65535 | F5: =FALSE() -> FALSE | G5: =FALSE() -> FALSE | H5: =TRUE() -> TRUE | I5: =FALSE() -> FALSE | J5: =FALSE() -> FALSE | K5: =FALSE() -> FALSE | L5: =FALSE() -> FALSE | M5: =TRUE() -> TRUE | N5: =TRUE() -> TRUE | R5: ws | S5: Worksheet | T5: (필수) | V5: 잠금 처리 대상 워크시트 객체 | W5: wsProtect_template(Worksheets("TARA_Report"))
B6: 2 | C6: Encrypt | E6: 65535 | F6: =FALSE() -> FALSE | G6: =FALSE() -> FALSE | H6: =TRUE() -> TRUE | I6: =FALSE() -> FALSE | J6: =FALSE() -> FALSE | K6: =FALSE() -> FALSE | L6: =FALSE() -> FALSE | M6: =TRUE() -> TRUE | N6: =TRUE() -> TRUE | R6: Password | S6: String | T6: (필수) | U6: Const | V6: 시트 보호(Unprotect 포함) 시 사용할 암호 | W6: Password:="MyPwd2026"
R7: InputColorRGB | S7: Variant | T7: Empty | U7: 선택 | V7: 입력셀로 인식할 채우기색의 RGB Long값. Empty면 색상 스캔 생략(기존 Locked 상태 유지). 노란색(255,255,0)은 65535 | W7: InputColorRGB:=65535
R8: ForceFullLock_NoException | S8: Boolean | T8: False | U8: 선택 | V8: True 시 색상과 무관하게 시트 전체를 예외 없이 잠금/False 시, InputColorRGB 조건에 따름 Ref.* 시트처럼 편집모드가 아니면 전부 잠가야 하는 경우 사용 | W8: ForceFullLock_NoException:=True
R9: UserInterfaceOnly | S9: Boolean | T9: False | U9: 선택 | V9: True 시 사용자는 편집 불가하지만 VBA 코드는 보호된 상태에서도 셀 값을 갱신 가능. TARA 종료 후 결과를 자동 기록해야 하는 시트에 사용 | W9: UserInterfaceOnly:=True
R10: AllowFormatting | S10: Boolean | T10: False | U10: 선택 | V10: 셀/열/행 서식 변경 허용 여부 (3개 옵션 통합). True 시 색상,글꼴,테두리 등 서식 변경 가능 | W10: AllowFormatting:=True
R11: AllowInserting | S11: Boolean | T11: False | U11: 선택 | V11: 행/열 삽입 허용 여부 (2개 옵션 통합) | W11: AllowInserting:=False
R12: AllowDeleting | S12: Boolean | T12: False | U12: 선택 | V12: 행/열 삭제 허용 여부 (2개 옵션 통합) | W12: AllowDeleting:=False
R13: AllowSorting | S13: Boolean | T13: False | U13: 선택 | V13: 정렬 기능 허용 여부 | W13: AllowSorting:=True
R14: AllowFiltering | S14: Boolean | T14: False | U14: 선택 | V14: 자동필터 사용 허용 여부 | W14: AllowFiltering:=True
R15: LockShapes | S15: Boolean | T15: True | U15: 선택 | V15: 일반 도형(텍스트박스, 이미지, AutoShape) 잠금 여부. 폼컨트롤(매크로 버튼)은 이 값과 무관하게 항상 예외 처리(고정)되어 클릭 가능 | W15: LockShapes:=False
R16: LockOLEObjects | S16: Boolean | T16: True | U16: 선택 | V16: 임베디드 OLE 개체(삽입된 파일 등) 잠금 여부 | W16: LockOLEObjects:=True

Sheet 안내
B4: 항목 | C4: 설명
B5: 작성 근거 | C5: 첨부 자가평가 워크북의 ProcessBP_Product 시트(27개 ASPICE 프로세스, 165개 BP/산출물)와 프로젝트 프로파일 시트의 기본 마일스톤 매핑(M-Car/Proto/P1/P2/SoP, '표준수행' 기준)을 그대로 사용.
B7: CA 정의 방식 | C7: 설계문서 3장 원칙에 따라 ASPICE 프로세스 1개 = CA(Control Account) 1개로 정의하되, SWE.3(상세설계/단위구현)·SWE.4(단위검증)는 ASW/BSW 계층별 담당(자체/외주)이 갈리므로 각각 2개 CA로 분리하여 총 29개 CA로 구성.
B9: WP 정의 방식 | C9: 설계문서 4장 원칙에 따라 각 BP/산출물 1개 = Discrete WP 1개로 정의. SWE.3·SWE.4는 ASW/BSW 두 벌로 복제되어 총 175개 WP.
B11: Discrete/LOE 구분 | C11: 설계문서 6장 원칙(PM/QA/CM은 혼합, 기술프로세스는 Discrete)에 따라 CA 유형을 우선 지정하고, '혼합' CA는 산출물명 키워드로 1차 제안함(수기 검토 필요 — WP_상세 시트 F열 참고).
B13: 입력 셀 색상 구분(중요) | C13: 파랑=계획단계 1회성 입력(PM/기획이 프로젝트 착수 시 확정: CAM 지정, 시나리오 선택, BAC 관련 가정, 최초작성비중 등) / 초록=진행중 담당자·CAM이 정기 입력(WP_상세 진도율·상태·근거자료, 실적MM_입력의 월별 실적MM, SWE34 채점) / 주황=진행중 PM·관리조직이 입력·검토(EVMS_대시보드 현재시점, 표본재검토 기록, 재기준선 로그, 배포게이트 상태). 노란색 셀은 남아있지 않음 — 모든 입력 셀이 이 3색 중 하나로 분류됨.
B15: 아직 반영되지 않은 것 | C15: ① 실제 MM/원가 배분(BAC 금액) — 설계문서 5장 원칙대로 산출물 진도와 별도로 타임시트 등에서 수집 필요. ② LOE_계정 시트의 공통경비/출장비는 ASPICE 산출물 구조 밖에 있으므로 별도 관리.
B17: 자가평가 워크북과의 연계 | C17: WP_상세 시트의 'BP#'는 원본 워크북의 M-Car~SoP 마일스톤 시트의 BP 번호와 동일하다. 마일스톤 자가평가에서 산출된 100점 환산 점수를 그대로 해당 WP의 진도율(%)로 사용하면 설계문서 4장의 BCWP 산정 방법과 일치한다.
B19: 프로젝트 프로파일 커스터마이징 필요 | C19: 원본 워크북의 '프로젝트 프로파일' 시트는 아직 비어 있어(신규/파생개발 유형 미지정) 기본값(표준수행)을 사용했다. 실제 파일럿 프로젝트가 파생개발이거나 일부 프로세스를 재사용/제외한다면, 그 시트를 먼저 채운 뒤 이 초안의 마일스톤 배정을 조정해야 한다.
B21: 경영보고_요약 시트(신규) | C21: SPI/CPI 용어 없이 정상/주의/위험 신호등만으로 프로젝트 상태를 보여주는 임원/보고용 시트. 전체 신호등이 '정상'이어도 하위 3개 CA는 항상 함께 표시해, 기존 신호등 방식이 놓쳤던 부분 CA 리스크를 보여준다. 근거가 필요하면 EVMS_대시보드로 내려가서 확인 가능.
B23: 프로젝트예산_현금성 시트(신규) | C23: CA_개요/실적MM_입력/EVMS_대시보드는 전부 MM(인월) 단위라 외주용역비·시작품 제작비 같은 현금성 프로젝트 예산이 보이지 않았다. 이 시트가 그 공백을 메운다 — BSW 외주개발/검증 용역비, 시작용 제어기 제작비(A/B샘플)를 계획금액(원) 기준으로 별도 추적하며, 진도율은 CA_개요의 CA평가점수를 그대로 재사용해 이중입력을 피한다. 노무단가 환산은 아직 하지 않으므로 MM 기반 EVMS와는 독립된 축으로 운영된다.
B27: 약어 | C27: 원어 | D27: 의미
B28: EVMS | C28: Earned Value Management System | D28: 획득가치 관리체계. 일정과 원가(성과)를 하나의 지표 체계로 통합 관리하는 기법
B29: WBS | C29: Work Breakdown Structure | D29: 작업분류체계. 프로젝트 범위를 계층적으로 분해한 구조
B30: CA | C30: Control Account | D30: 통제계정. WBS와 조직(책임자)이 교차하는 지점으로 EVMS 성과측정의 기본 단위
B31: WP | C31: Work Package | D31: 작업패키지. CA 하위의 더 세분화된 실행단위(성과측정의 최소 단위)
B32: CAM | C32: Control Account Manager | D32: 통제계정 관리자. 특정 CA의 일정/원가/성과에 대한 책임자
B33: LOE | C33: Level of Effort | D33: 노력수준 활동. 명확한 산출물 없이 시간에 비례해 진행되는 활동
B34: PV / BCWS | C34: Planned Value / Budgeted Cost of Work Scheduled | D34: 계획가치. 특정 시점까지 계획된 작업량의 예산가치
B35: EV / BCWP | C35: Earned Value / Budgeted Cost of Work Performed | D35: 획득가치. 실제 완료된 작업량을 예산가치로 환산한 값(성과)
B36: AC / ACWP | C36: Actual Cost / Actual Cost of Work Performed | D36: 실적원가. 실제 투입된 원가
B37: SV | C37: Schedule Variance | D37: 일정차이 = BCWP − BCWS
B38: CV | C38: Cost Variance | D38: 원가차이 = BCWP − ACWP
... B48: ANSI/EIA-748 | C48: — | D48: 미국 EVMS 표준(32개 가이드라인, 정통 EVMS의 근거 표준)

Sheet 경영보고_요약
B4: 지표 | C4: 값
B5: 기준 시점 | C5: ="경과 "&EVMS_대시보드!N4&"개월차 기준" -> 경과 5개월차 기준
B6: 전체 진행률 | C6: =IFERROR(EVMS_대시보드!F35/EVMS_대시보드!D35,0) -> 0.78543286
B7: 예산 소진율 | C7: =IFERROR(EVMS_대시보드!G35/EVMS_대시보드!D35,0) -> 0.39964474
B8: 전체 신호등 | C8: =IF(AND(EVMS_대시보드!J35=0,EVMS_대시보드!K35=0),"미시작",IF(OR(EVMS_대시보드!J35<0.8,EVMS_대시보드!K35<0.8),"위험",IF(OR(EVMS_대시보드!J35<0.9,EVMS_대시보드!K35<0.9),"주의","정상"))) -> 정상
B9: 현금성 예산 집행률 | C9: =IFERROR(프로젝트예산_현금성!H11/프로젝트예산_현금성!D11,0) -> 0.68210526
B10: 현금성 예산 신호등 | C10: =IF(AND(프로젝트예산_현금성!D11=0,프로젝트예산_현금성!H11=0),"미시작",IF(OR(IFERROR(프로젝트예산_현금성!G11/프로젝트예산_현금성!K11,0)<0.8,IFERROR(프로젝트예산_현금성!G11/프로젝트예산_현금성!H11,0)<0.8),"위험",IF(OR(IFERROR(프로젝트예산_현금성!G11/프로젝트예산_현금성!K11,0)<0.9,IFERROR(프로젝트예산_현금성!G11/프로젝트예산_현금성!H11,0)<0.9),"주의","정상"))) -> 위험
B11: 통합 진행률 (MM원화+현금성 합산) | C11: =IFERROR((EVMS_대시보드!R35+프로젝트예산_현금성!G11)/(EVMS_대시보드!P35+프로젝트예산_현금성!D11),0) -> 0.80982737
B12: 통합 신호등 (MM원화+현금성 합산) | C12: =IF(AND((EVMS_대시보드!Q35+프로젝트예산_현금성!K11)=0,(EVMS_대시보드!S35+프로젝트예산_현금성!H11)=0),"미시작",IF(IFERROR((EVMS_대시보드!R35+프로젝트예산_현금성!G11)/(EVMS_대시보드!S35+프로젝트예산_현금성!H11),0)<0.8,"위험",IF(IFERROR((EVMS_대시보드!R35+프로젝트예산_현금성!G11)/(EVMS_대시보드!S35+프로젝트예산_현금성!H11),0)<0.9,"주의","정상"))) -> 정상
B14: 가장 주의가 필요한 영역 (하위 3개 CA)
B15: 순위 | C15: 참고코드 | D15: CA명 | E15: 담당자 | F15: 신호등 | G15: 핵심메모
B16: 1 | C16: =INDEX(EVMS_대시보드!$B$5:$B$33,MATCH(SMALL(EVMS_대시보드!$O$5:$O$33,1),EVMS_대시보드!$O$5:$O$33,0)) -> VAL.1 | D16: =INDEX(EVMS_대시보드!$C$5:$C$33,MATCH($C16,EVMS_대시보드!$B$5:$B$33,0)) -> 제품확인(Validation) | E16: =IFERROR(INDEX(CA_개요!$G$5:$G$33,MATCH($C16,CA_개요!$B$5:$B$33,0)),"") -> 0 | F16: =IF(AND(INDEX(EVMS_대시보드!$J$5:$J$33,MATCH($C16,EVMS_대시보드!$B$5:$B$33,0))=0,INDEX(EVMS_대시보드!$K$5:$K$33,MATCH($C16,EVMS_대시보드!$B$5:$B$33,0))=0),"미시작",IF(OR(INDEX(EVMS_대시보드!$J$5:$J$33,MATCH($C16,EVMS_대시보드!$B$5:$B$33,0))<0.8,INDEX(EVMS_대시보드!$K$5:$K$33,MATCH($C16,EVMS_대시보드!$B$5:$B$33,0))<0.8),"위험",IF(OR(INDEX(EVMS_대시보드!$J$5:$J$33,MATCH($C16,EVMS_대시보드!$B$5:$B$33,0))<0.9,INDEX(EVMS_대시보드!$K$5:$K$33,MATCH($C16,EVMS_대시보드!$B$5:$B$33,0))<0.9),"주의","정상"))) -> 미시작 | G16: =IFERROR(INDEX(CA_개요!$K$5:$K$33,MATCH($C16,CA_개요!$B$5:$B$33,0)),"") -> 0
B17: 2 | C17: =INDEX(EVMS_대시보드!$B$5:$B$33,MATCH(SMALL(EVMS_대시보드!$O$5:$O$33,2),EVMS_대시보드!$O$5:$O$33,0)) -> SYS.5 | D17: =INDEX(EVMS_대시보드!$C$5:$C$33,MATCH($C17,EVMS_대시보드!$B$5:$B$33,0)) -> 시스템 검증 | E17: =IFERROR(INDEX(CA_개요!$G$5:$G$33,MATCH($C17,CA_개요!$B$5:$B$33,0)),"") -> 0 | F17: =IF(AND(INDEX(EVMS_대시보드!$J$5:$J$33,MATCH($C17,EVMS_대시보드!$B$5:$B$33,0))=0,INDEX(EVMS_대시보드!$K$5:$K$33,MATCH($C17,EVMS_대시보드!$B$5:$B$33,0))=0),"미시작",IF(OR(INDEX(EVMS_대시보드!$J$5:$J$33,MATCH($C17,EVMS_대시보드!$B$5:$B$33,0))<0.8,INDEX(EVMS_대시보드!$K$5:$K$33,MATCH($C17,EVMS_대시보드!$B$5:$B$33,0))<0.8),"위험",IF(OR(INDEX(EVMS_대시보드!$J$5:$J$33,MATCH($C17,EVMS_대시보드!$B$5:$B$33,0))<0.9,INDEX(EVMS_대시보드!$K$5:$K$33,MATCH($C17,EVMS_대시보드!$B$5:$B$33,0))<0.9),"주의","정상"))) -> 위험 | G17: =IFERROR(INDEX(CA_개요!$K$5:$K$33,MATCH($C17,CA_개요!$B$5:$B$33,0)),"") -> 0
B18: 3 | C18: =INDEX(EVMS_대시보드!$B$5:$B$33,MATCH(SMALL(EVMS_대시보드!$O$5:$O$33,3),EVMS_대시보드!$O$5:$O$33,0)) -> SWE.6 | D18: =INDEX(EVMS_대시보드!$C$5:$C$33,MATCH($C18,EVMS_대시보드!$B$5:$B$33,0)) -> SW 검증 | E18: =IFERROR(INDEX(CA_개요!$G$5:$G$33,MATCH($C18,CA_개요!$B$5:$B$33,0)),"") -> 0 | F18: =IF(AND(INDEX(EVMS_대시보드!$J$5:$J$33,MATCH($C18,EVMS_대시보드!$B$5:$B$33,0))=0,INDEX(EVMS_대시보드!$K$5:$K$33,MATCH($C18,EVMS_대시보드!$B$5:$B$33,0))=0),"미시작",IF(OR(INDEX(EVMS_대시보드!$J$5:$J$33,MATCH($C18,EVMS_대시보드!$B$5:$B$33,0))<0.8,INDEX(EVMS_대시보드!$K$5:$K$33,MATCH($C18,EVMS_대시보드!$B$5:$B$33,0))<0.8),"위험",IF(OR(INDEX(EVMS_대시보드!$J$5:$J$33,MATCH($C18,EVMS_대시보드!$B$5:$B$33,0))<0.9,INDEX(EVMS_대시보드!$K$5:$K$33,MATCH($C18,EVMS_대시보드!$B$5:$B$33,0))<0.9),"주의","정상"))) -> 위험 | G18: =IFERROR(INDEX(CA_개요!$K$5:$K$33,MATCH($C18,CA_개요!$B$5:$B$33,0)),"") -> 0
B20: 전체 CA 신호등 목록
B21: CA명 | C21: 카테고리 | D21: 신호등
B22: =CA_개요!C5 -> 협약/공급자 모니터링 | C22: =CA_개요!E5 -> 조달 | D22: =IF(AND(EVMS_대시보드!J5=0,EVMS_대시보드!K5=0),"미시작",IF(OR(EVMS_대시보드!J5<0.8,EVMS_대시보드!K5<0.8),"위험",IF(OR(EVMS_대시보드!J5<0.9,EVMS_대시보드!K5<0.9),"주의","정상"))) -> 정상
B23: =CA_개요!C6 -> 제품 릴리스 관리 | C23: =CA_개요!E6 -> 릴리스 | D23: =IF(AND(EVMS_대시보드!J6=0,EVMS_대시보드!K6=0),"미시작",IF(OR(EVMS_대시보드!J6<0.8,EVMS_대시보드!K6<0.8),"위험",IF(OR(EVMS_대시보드!J6<0.9,EVMS_대시보드!K6<0.9),"주의","정상"))) -> 정상
B24: =CA_개요!C7 -> 프로젝트 관리 | C24: =CA_개요!E7 -> 관리/LOE | D24: =IF(AND(EVMS_대시보드!J7=0,EVMS_대시보드!K7=0),"미시작",IF(OR(EVMS_대시보드!J7<0.8,EVMS_대시보드!K7<0.8),"위험",IF(OR(EVMS_대시보드!J7<0.9,EVMS_대시보드!K7<0.9),"주의","정상"))) -> 정상
B25: =CA_개요!C8 -> 품질보증(QA) | C25: =CA_개요!E8 -> 관리/LOE | D25: =IF(AND(EVMS_대시보드!J8=0,EVMS_대시보드!K8=0),"미시작",IF(OR(EVMS_대시보드!J8<0.8,EVMS_대시보드!K8<0.8),"위험",IF(OR(EVMS_대시보드!J8<0.9,EVMS_대시보드!K8<0.9),"주의","정상"))) -> 정상
B26: =CA_개요!C9 -> 형상관리(CM) | C26: =CA_개요!E9 -> 관리/LOE | D26: =IF(AND(EVMS_대시보드!J9=0,EVMS_대시보드!K9=0),"미시작",IF(OR(EVMS_대시보드!J9<0.8,EVMS_대시보드!K9<0.8),"위험",IF(OR(EVMS_대시보드!J9<0.9,EVMS_대시보드!K9<0.9),"주의","정상"))) -> 정상
B27: =CA_개요!C10 -> 문제해결관리 | C27: =CA_개요!E10 -> 관리/LOE | D27: =IF(AND(EVMS_대시보드!J10=0,EVMS_대시보드!K10=0),"미시작",IF(OR(EVMS_대시보드!J10<0.8,EVMS_대시보드!K10<0.8),"위험",IF(OR(EVMS_대시보드!J10<0.9,EVMS_대시보드!K10<0.9),"주의","정상"))) -> 정상
B28: =CA_개요!C11 -> 변경요청관리 | C28: =CA_개요!E11 -> 관리/LOE | D28: =IF(AND(EVMS_대시보드!J11=0,EVMS_대시보드!K11=0),"미시작",IF(OR(EVMS_대시보드!J11<0.8,EVMS_대시보드!K11<0.8),"위험",IF(OR(EVMS_대시보드!J11<0.9,EVMS_대시보드!K11<0.9),"주의","정상"))) -> 정상
B29: =CA_개요!C12 -> ML 데이터관리(ASW에 포함) | C29: =CA_개요!E12 -> ASW | D29: =IF(AND(EVMS_대시보드!J12=0,EVMS_대시보드!K12=0),"미시작",IF(OR(EVMS_대시보드!J12<0.8,EVMS_대시보드!K12<0.8),"위험",IF(OR(EVMS_대시보드!J12<0.9,EVMS_대시보드!K12<0.9),"주의","정상"))) -> 정상
B30: =CA_개요!C13 -> 시스템 요구사항분석 | C30: =CA_개요!E13 -> 시스템 | D30: =IF(AND(EVMS_대시보드!J13=0,EVMS_대시보드!K13=0),"미시작",IF(OR(EVMS_대시보드!J13<0.8,EVMS_대시보드!K13<0.8),"위험",IF(OR(EVMS_대시보드!J13<0.9,EVMS_대시보드!K13<0.9),"주의","정상"))) -> 정상
B31: =CA_개요!C14 -> 시스템 아키텍처설계 | C31: =CA_개요!E14 -> 시스템 | D31: =IF(AND(EVMS_대시보드!J14=0,EVMS_대시보드!K14=0),"미시작",IF(OR(EVMS_대시보드!J14<0.8,EVMS_대시보드!K14<0.8),"위험",IF(OR(EVMS_대시보드!J14<0.9,EVMS_대시보드!K14<0.9),"주의","정상"))) -> 정상
B32: =CA_개요!C15 -> 시스템 통합/통합검증 | C32: =CA_개요!E15 -> 시스템 | D32: =IF(AND(EVMS_대시보드!J15=0,EVMS_대시보드!K15=0),"미시작",IF(OR(EVMS_대시보드!J15<0.8,EVMS_대시보드!K15<0.8),"위험",IF(OR(EVMS_대시보드!J15<0.9,EVMS_대시보드!K15<0.9),"주의","정상"))) -> 정상
B33: =CA_개요!C16 -> 시스템 검증 | C33: =CA_개요!E16 -> 시스템 | D33: =IF(AND(EVMS_대시보드!J16=0,EVMS_대시보드!K16=0),"미시작",IF(OR(EVMS_대시보드!J16<0.8,EVMS_대시보드!K16<0.8),"위험",IF(OR(EVMS_대시보드!J16<0.9,EVMS_대시보드!K16<0.9),"주의","정상"))) -> 위험
... B50: =CA_개요!C33 -> HW 요구사항검증 | C50: =CA_개요!E33 -> HW | D50: =IF(AND(EVMS_대시보드!J33=0,EVMS_대시보드!K33=0),"미시작",IF(OR(EVMS_대시보드!J33<0.8,EVMS_대시보드!K33<0.8),"위험",IF(OR(EVMS_대시보드!J33<0.9,EVMS_대시보드!K33<0.9),"주의","정상"))) -> 위험
B52: 기존 신호등 방식과 달라진 점
B53: • | C53: 전체가 '정상'으로 보여도 위 Top3 표에서 실제로 어떤 영역이 취약한지 항상 함께 보여준다(설계문서 15장: 전체 지표만으로는 CA 단위 문제를 가릴 수 있음이 6개 파일럿 시나리오에서 실증됨).
B54: • | C54: 신호등 색은 담당자의 주관적 판단이 아니라 WP_상세의 진도율과 실적MM_입력의 실적 공수를 결합한 계산값(EVMS_대시보드)에서 자동 산출된다.
B55: • | C55: 보고받는 사람은 이 시트만 보면 되고, 근거가 필요하면 EVMS_대시보드·WP_상세로 내려가서 확인할 수 있다.

Sheet CA_개요
A4: CA No | B4: Process(ASPICE) | C4: CA명(국문) | D4: 관리유형 | E4: 카테고리 | F4: 기본 마일스톤 배정 | G4: CAM(담당자) | H4: BAC 배분비중(%) | I4: 소속 WP 개수 | J4: CA 평가점수(100점,자동) | K4: 비고
A5: 1 | B5: ACQ.4 | C5: 협약/공급자 모니터링 | D5: 혼합 | E5: 조달 | F5: M-Car~P1 | H5: =INDEX(가정!$C$7:$L$9,MATCH(가정!$C$4,가정!$B$7:$B$9,0),MATCH(E5,가정!$C$6:$L$6,0))*(I5/SUMIF($E$5:$E$33,E5,$I$5:$I$33)) -> 0.08 | I5: =COUNTIF(WP_상세!$B$5:$B$500,B5) -> 5 | J5: =IFERROR(ROUND(AVERAGEIF(WP_상세!$B$5:$B$500,B5,WP_상세!$L$5:$L$500)*100,1),0) -> 85 | K5: 외주용역(개발/검증시험) 계약이 있는 경우 사용. 외주 비중이 클수록 조달 CA 비중도 커짐(가정 시트 시나리오 참조)
A6: 2 | B6: SPL.2 | C6: 제품 릴리스 관리 | D6: Discrete | E6: 릴리스 | F6: 릴리즈이력 별도관리 | H6: =INDEX(가정!$C$7:$L$9,MATCH(가정!$C$4,가정!$B$7:$B$9,0),MATCH(E6,가정!$C$6:$L$6,0))*(I6/SUMIF($E$5:$E$33,E6,$I$5:$I$33)) -> 0.04 | I6: =COUNTIF(WP_상세!$B$5:$B$500,B6) -> 8 | J6: =IFERROR(ROUND(AVERAGEIF(WP_상세!$B$5:$B$500,B6,WP_상세!$L$5:$L$500)*100,1),0) -> 75 | K6: 설계문서 8장의 '고객 합의 SW 배포' 마일스톤과 직결되는 CA. 원본 워크북 릴리즈이력 시트로 별도 상세관리
A7: 3 | B7: MAN.3 | C7: 프로젝트 관리 | D7: 혼합(LOE 위주) | E7: 관리/LOE | F7: M-Car~P1 | H7: =INDEX(가정!$C$7:$L$9,MATCH(가정!$C$4,가정!$B$7:$B$9,0),MATCH(E7,가정!$C$6:$L$6,0))*(I7/SUMIF($E$5:$E$33,E7,$I$5:$I$33)) -> 0.047368421 | I7: =COUNTIF(WP_상세!$B$5:$B$500,B7) -> 10 | J7: =IFERROR(ROUND(AVERAGEIF(WP_상세!$B$5:$B$500,B7,WP_상세!$L$5:$L$500)*100,1),0) -> 85 | K7: BP10(진척현황보고서)만 LOE 제안, 나머지는 1회성 계획서로 Discrete 제안
A8: 4 | B8: SUP.1 | C8: 품질보증(QA) | D8: 혼합 | E8: 관리/LOE | F8: M-Car~P1 | H8: =INDEX(가정!$C$7:$L$9,MATCH(가정!$C$4,가정!$B$7:$B$9,0),MATCH(E8,가정!$C$6:$L$6,0))*(I8/SUMIF($E$5:$E$33,E8,$I$5:$I$33)) -> 0.033157895 | I8: =COUNTIF(WP_상세!$B$5:$B$500,B8) -> 7 | J8: =IFERROR(ROUND(AVERAGEIF(WP_상세!$B$5:$B$500,B8,WP_상세!$L$5:$L$500)*100,1),0) -> 67.9 | K8: 정기 QA활동은 LOE, 감사보고서 발행 등 이벤트는 Discrete로 WP_상세에서 구분
A9: 5 | B9: SUP.8 | C9: 형상관리(CM) | D9: 혼합 | E9: 관리/LOE | F9: M-Car~P1 | H9: =INDEX(가정!$C$7:$L$9,MATCH(가정!$C$4,가정!$B$7:$B$9,0),MATCH(E9,가정!$C$6:$L$6,0))*(I9/SUMIF($E$5:$E$33,E9,$I$5:$I$33)) -> 0.037894737 | I9: =COUNTIF(WP_상세!$B$5:$B$500,B9) -> 8 | J9: =IFERROR(ROUND(AVERAGEIF(WP_상세!$B$5:$B$500,B9,WP_상세!$L$5:$L$500)*100,1),0) -> 71.9 | K9: 일상 형상통제는 LOE, 베이스라인 수립 등 이벤트는 Discrete로 WP_상세에서 구분
A10: 6 | B10: SUP.9 | C10: 문제해결관리 | D10: LOE 위주 | E10: 관리/LOE | F10: Proto~P1(반복:M-Car,Proto,P1) | H10: =INDEX(가정!$C$7:$L$9,MATCH(가정!$C$4,가정!$B$7:$B$9,0),MATCH(E10,가정!$C$6:$L$6,0))*(I10/SUMIF($E$5:$E$33,E10,$I$5:$I$33)) -> 0.033157895 | I10: =COUNTIF(WP_상세!$B$5:$B$500,B10) -> 7 | J10: =IFERROR(ROUND(AVERAGEIF(WP_상세!$B$5:$B$500,B10,WP_상세!$L$5:$L$500)*100,1),0) -> 67.9 | K10: 이슈 특성상 대부분 LOE 제안. 반복평가(M-Car/Proto/P1) 마일스톤 스냅샷은 원본 워크북 참조
A11: 7 | B11: SUP.10 | C11: 변경요청관리 | D11: 혼합 | E11: 관리/LOE | F11: Proto~P1 | H11: =INDEX(가정!$C$7:$L$9,MATCH(가정!$C$4,가정!$B$7:$B$9,0),MATCH(E11,가정!$C$6:$L$6,0))*(I11/SUMIF($E$5:$E$33,E11,$I$5:$I$33)) -> 0.028421053 | I11: =COUNTIF(WP_상세!$B$5:$B$500,B11) -> 6 | J11: =IFERROR(ROUND(AVERAGEIF(WP_상세!$B$5:$B$500,B11,WP_상세!$L$5:$L$500)*100,1),0) -> 62.5 | K11: 일상 변경요청 처리는 LOE, 추적성매트릭스 등은 Discrete로 WP_상세에서 구분
A12: 8 | B12: SUP.11 | C12: ML 데이터관리(ASW에 포함) | D12: Discrete | E12: ASW | F12: M-Car~P1 | H12: =INDEX(가정!$C$7:$L$9,MATCH(가정!$C$4,가정!$B$7:$B$9,0),MATCH(E12,가정!$C$6:$L$6,0))*(I12/SUMIF($E$5:$E$33,E12,$I$5:$I$33)) -> 0.032195122 | I12: =COUNTIF(WP_상세!$B$5:$B$500,B12) -> 6 | J12: =IFERROR(ROUND(AVERAGEIF(WP_상세!$B$5:$B$500,B12,WP_상세!$L$5:$L$500)*100,1),0) -> 75 | K12: ML을 별도 관리하지 않고 ASW의 일부로 취급(가정)하되, 원본 워크북 BP 구조를 유지하기 위해 CA는 별도로 남김
A13: 9 | B13: SYS.2 | C13: 시스템 요구사항분석 | D13: Discrete | E13: 시스템 | F13: M-Car | H13: =INDEX(가정!$C$7:$L$9,MATCH(가정!$C$4,가정!$B$7:$B$9,0),MATCH(E13,가정!$C$6:$L$6,0))*(I13/SUMIF($E$5:$E$33,E13,$I$5:$I$33)) -> 0.022857143 | I13: =COUNTIF(WP_상세!$B$5:$B$500,B13) -> 6 | J13: =IFERROR(ROUND(AVERAGEIF(WP_상세!$B$5:$B$500,B13,WP_상세!$L$5:$L$500)*100,1),0) -> 100
A14: 10 | B14: SYS.3 | C14: 시스템 아키텍처설계 | D14: Discrete | E14: 시스템 | F14: M-Car | H14: =INDEX(가정!$C$7:$L$9,MATCH(가정!$C$4,가정!$B$7:$B$9,0),MATCH(E14,가정!$C$6:$L$6,0))*(I14/SUMIF($E$5:$E$33,E14,$I$5:$I$33)) -> 0.019047619 | I14: =COUNTIF(WP_상세!$B$5:$B$500,B14) -> 5 | J14: =IFERROR(ROUND(AVERAGEIF(WP_상세!$B$5:$B$500,B14,WP_상세!$L$5:$L$500)*100,1),0) -> 100
A15: 11 | B15: SYS.4 | C15: 시스템 통합/통합검증 | D15: Discrete | E15: 시스템 | F15: Proto~P1 | H15: =INDEX(가정!$C$7:$L$9,MATCH(가정!$C$4,가정!$B$7:$B$9,0),MATCH(E15,가정!$C$6:$L$6,0))*(I15/SUMIF($E$5:$E$33,E15,$I$5:$I$33)) -> 0.019047619 | I15: =COUNTIF(WP_상세!$B$5:$B$500,B15) -> 5 | J15: =IFERROR(ROUND(AVERAGEIF(WP_상세!$B$5:$B$500,B15,WP_상세!$L$5:$L$500)*100,1),0) -> 55
A16: 12 | B16: SYS.5 | C16: 시스템 검증 | D16: Discrete | E16: 시스템 | F16: P1~P2 | H16: =INDEX(가정!$C$7:$L$9,MATCH(가정!$C$4,가정!$B$7:$B$9,0),MATCH(E16,가정!$C$6:$L$6,0))*(I16/SUMIF($E$5:$E$33,E16,$I$5:$I$33)) -> 0.019047619 | I16: =COUNTIF(WP_상세!$B$5:$B$500,B16) -> 5 | J16: =IFERROR(ROUND(AVERAGEIF(WP_상세!$B$5:$B$500,B16,WP_상세!$L$5:$L$500)*100,1),0) -> 10
A17: 13 | B17: SWE.1 | C17: SW 요구사항분석 | D17: Discrete | E17: 공통(SW설계) | F17: M-Car | H17: =INDEX(가정!$C$7:$L$9,MATCH(가정!$C$4,가정!$B$7:$B$9,0),MATCH(E17,가정!$C$6:$L$6,0))*(I17/SUMIF($E$5:$E$33,E17,$I$5:$I$33)) -> 0.032727273 | I17: =COUNTIF(WP_상세!$B$5:$B$500,B17) -> 6 | J17: =IFERROR(ROUND(AVERAGEIF(WP_상세!$B$5:$B$500,B17,WP_상세!$L$5:$L$500)*100,1),0) -> 100
A18: 14 | B18: SWE.2 | C18: SW 아키텍처설계 | D18: Discrete | E18: 공통(SW설계) | F18: M-Car | H18: =INDEX(가정!$C$7:$L$9,MATCH(가정!$C$4,가정!$B$7:$B$9,0),MATCH(E18,가정!$C$6:$L$6,0))*(I18/SUMIF($E$5:$E$33,E18,$I$5:$I$33)) -> 0.027272727 | I18: =COUNTIF(WP_상세!$B$5:$B$500,B18) -> 5 | J18: =IFERROR(ROUND(AVERAGEIF(WP_상세!$B$5:$B$500,B18,WP_상세!$L$5:$L$500)*100,1),0) -> 100
A19: 15 | B19: SWE.3-ASW | C19: SW 상세설계/단위구현(ASW) | D19: Discrete | E19: ASW | F19: Proto | H19: =INDEX(가정!$C$7:$L$9,MATCH(가정!$C$4,가정!$B$7:$B$9,0),MATCH(E19,가정!$C$6:$L$6,0))*(I19/SUMIF($E$5:$E$33,E19,$I$5:$I$33)) -> 0.026829268 | I19: =COUNTIF(WP_상세!$B$5:$B$500,B19) -> 5 | J19: =IFERROR(ROUND(AVERAGEIF(WP_상세!$B$5:$B$500,B19,WP_상세!$L$5:$L$500)*100,1),0) -> 100 | K19: 원본 워크북은 계층 구분이 없어 SWE.3 BP를 그대로 복제. 자가평가 시 ASW분과 BSW분을 각자 채점 필요
A20: 16 | B20: SWE.3-BSW | C20: SW 상세설계/단위구현(BSW) | D20: Discrete | E20: BSW | F20: Proto | H20: =INDEX(가정!$C$7:$L$9,MATCH(가정!$C$4,가정!$B$7:$B$9,0),MATCH(E20,가정!$C$6:$L$6,0))*(I20/SUMIF($E$5:$E$33,E20,$I$5:$I$33)) -> 0.1 | I20: =COUNTIF(WP_상세!$B$5:$B$500,B20) -> 5 | J20: =IFERROR(ROUND(AVERAGEIF(WP_상세!$B$5:$B$500,B20,WP_상세!$L$5:$L$500)*100,1),0) -> 100 | K20: 외주 또는 AUTOSAR 구매 시 이 CA가 조달(ACQ.4)과 함께 커짐. 원본 워크북은 계층 구분이 없어 SWE.3 BP를 그대로 복제
A21: 17 | B21: SWE.4-ASW | C21: SW 단위검증(ASW) | D21: Discrete | E21: ASW | F21: Proto | H21: =INDEX(가정!$C$7:$L$9,MATCH(가정!$C$4,가정!$B$7:$B$9,0),MATCH(E21,가정!$C$6:$L$6,0))*(I21/SUMIF($E$5:$E$33,E21,$I$5:$I$33)) -> 0.026829268 | I21: =COUNTIF(WP_상세!$B$5:$B$500,B21) -> 5 | J21: =IFERROR(ROUND(AVERAGEIF(WP_상세!$B$5:$B$500,B21,WP_상세!$L$5:$L$500)*100,1),0) -> 100 | K21: 원본 워크북은 계층 구분이 없어 SWE.4 BP를 그대로 복제. 자가평가 시 ASW분과 BSW분을 각자 채점 필요
A22: 18 | B22: SWE.4-BSW | C22: SW 단위검증(BSW) | D22: Discrete | E22: BSW | F22: Proto | H22: =INDEX(가정!$C$7:$L$9,MATCH(가정!$C$4,가정!$B$7:$B$9,0),MATCH(E22,가정!$C$6:$L$6,0))*(I22/SUMIF($E$5:$E$33,E22,$I$5:$I$33)) -> 0.1 | I22: =COUNTIF(WP_상세!$B$5:$B$500,B22) -> 5 | J22: =IFERROR(ROUND(AVERAGEIF(WP_상세!$B$5:$B$500,B22,WP_상세!$L$5:$L$500)*100,1),0) -> 100 | K22: 외주 또는 AUTOSAR 구매 시 이 CA가 조달(ACQ.4)과 함께 커짐. 원본 워크북은 계층 구분이 없어 SWE.4 BP를 그대로 복제
A23: 19 | B23: SWE.5 | C23: SW 통합/통합검증 | D23: Discrete | E23: 통합 | F23: Proto~P1 | H23: =INDEX(가정!$C$7:$L$9,MATCH(가정!$C$4,가정!$B$7:$B$9,0),MATCH(E23,가정!$C$6:$L$6,0))*(I23/SUMIF($E$5:$E$33,E23,$I$5:$I$33)) -> 0.06 | I23: =COUNTIF(WP_상세!$B$5:$B$500,B23) -> 7 | J23: =IFERROR(ROUND(AVERAGEIF(WP_상세!$B$5:$B$500,B23,WP_상세!$L$5:$L$500)*100,1),0) -> 57.1
A24: 20 | B24: SWE.6 | C24: SW 검증 | D24: Discrete | E24: 검증 | F24: P1~P2 | H24: =INDEX(가정!$C$7:$L$9,MATCH(가정!$C$4,가정!$B$7:$B$9,0),MATCH(E24,가정!$C$6:$L$6,0))*(I24/SUMIF($E$5:$E$33,E24,$I$5:$I$33)) -> 0.01 | I24: =COUNTIF(WP_상세!$B$5:$B$500,B24) -> 5 | J24: =IFERROR(ROUND(AVERAGEIF(WP_상세!$B$5:$B$500,B24,WP_상세!$L$5:$L$500)*100,1),0) -> 10
A25: 21 | B25: VAL.1 | C25: 제품확인(Validation) | D25: Discrete | E25: 검증 | F25: P2 | H25: =INDEX(가정!$C$7:$L$9,MATCH(가정!$C$4,가정!$B$7:$B$9,0),MATCH(E25,가정!$C$6:$L$6,0))*(I25/SUMIF($E$5:$E$33,E25,$I$5:$I$33)) -> 0.01 | I25: =COUNTIF(WP_상세!$B$5:$B$500,B25) -> 5 | J25: =IFERROR(ROUND(AVERAGEIF(WP_상세!$B$5:$B$500,B25,WP_상세!$L$5:$L$500)*100,1),0) -> 0
A26: 22 | B26: MLE.1 | C26: ML 요구사항분석(ASW에 포함) | D26: Discrete | E26: ASW | F26: M-Car | H26: =INDEX(가정!$C$7:$L$9,MATCH(가정!$C$4,가정!$B$7:$B$9,0),MATCH(E26,가정!$C$6:$L$6,0))*(I26/SUMIF($E$5:$E$33,E26,$I$5:$I$33)) -> 0.032195122 | I26: =COUNTIF(WP_상세!$B$5:$B$500,B26) -> 6 | J26: =IFERROR(ROUND(AVERAGEIF(WP_상세!$B$5:$B$500,B26,WP_상세!$L$5:$L$500)*100,1),0) -> 100 | K26: ML을 별도 관리하지 않고 ASW의 일부로 취급(가정)
A27: 23 | B27: MLE.2 | C27: ML 아키텍처설계(ASW에 포함) | D27: Discrete | E27: ASW | F27: M-Car | H27: =INDEX(가정!$C$7:$L$9,MATCH(가정!$C$4,가정!$B$7:$B$9,0),MATCH(E27,가정!$C$6:$L$6,0))*(I27/SUMIF($E$5:$E$33,E27,$I$5:$I$33)) -> 0.037560976 | I27: =COUNTIF(WP_상세!$B$5:$B$500,B27) -> 7 | J27: =IFERROR(ROUND(AVERAGEIF(WP_상세!$B$5:$B$500,B27,WP_상세!$L$5:$L$500)*100,1),0) -> 100 | K27: ML을 별도 관리하지 않고 ASW의 일부로 취급(가정)
A28: 24 | B28: MLE.3 | C28: ML 훈련/검증(ASW에 포함) | D28: Discrete | E28: ASW | F28: Proto~P1 | H28: =INDEX(가정!$C$7:$L$9,MATCH(가정!$C$4,가정!$B$7:$B$9,0),MATCH(E28,가정!$C$6:$L$6,0))*(I28/SUMIF($E$5:$E$33,E28,$I$5:$I$33)) -> 0.026829268 | I28: =COUNTIF(WP_상세!$B$5:$B$500,B28) -> 5 | J28: =IFERROR(ROUND(AVERAGEIF(WP_상세!$B$5:$B$500,B28,WP_상세!$L$5:$L$500)*100,1),0) -> 55 | K28: ML을 별도 관리하지 않고 ASW의 일부로 취급(가정)
A29: 25 | B29: MLE.4 | C29: ML 테스트(ASW에 포함) | D29: Discrete | E29: ASW | F29: P1~P2 | H29: =INDEX(가정!$C$7:$L$9,MATCH(가정!$C$4,가정!$B$7:$B$9,0),MATCH(E29,가정!$C$6:$L$6,0))*(I29/SUMIF($E$5:$E$33,E29,$I$5:$I$33)) -> 0.037560976 | I29: =COUNTIF(WP_상세!$B$5:$B$500,B29) -> 7 | J29: =IFERROR(ROUND(AVERAGEIF(WP_상세!$B$5:$B$500,B29,WP_상세!$L$5:$L$500)*100,1),0) -> 10.7 | K29: ML을 별도 관리하지 않고 ASW의 일부로 취급(가정)
A30: 26 | B30: HWE.1 | C30: HW 요구사항분석 | D30: Discrete | E30: HW | F30: M-Car | H30: =INDEX(가정!$C$7:$L$9,MATCH(가정!$C$4,가정!$B$7:$B$9,0),MATCH(E30,가정!$C$6:$L$6,0))*(I30/SUMIF($E$5:$E$33,E30,$I$5:$I$33)) -> 0.015 | I30: =COUNTIF(WP_상세!$B$5:$B$500,B30) -> 6 | J30: =IFERROR(ROUND(AVERAGEIF(WP_상세!$B$5:$B$500,B30,WP_상세!$L$5:$L$500)*100,1),0) -> 100 | K30: A/B 샘플 개발 등 HW 병행개발 존재를 가정하여 실질 비중 배정
A31: 27 | B31: HWE.2 | C31: HW 아키텍처/상세설계 | D31: Discrete | E31: HW | F31: M-Car | H31: =INDEX(가정!$C$7:$L$9,MATCH(가정!$C$4,가정!$B$7:$B$9,0),MATCH(E31,가정!$C$6:$L$6,0))*(I31/SUMIF($E$5:$E$33,E31,$I$5:$I$33)) -> 0.015 | I31: =COUNTIF(WP_상세!$B$5:$B$500,B31) -> 6 | J31: =IFERROR(ROUND(AVERAGEIF(WP_상세!$B$5:$B$500,B31,WP_상세!$L$5:$L$500)*100,1),0) -> 100 | K31: A/B 샘플 개발 등 HW 병행개발 존재를 가정하여 실질 비중 배정
A32: 28 | B32: HWE.3 | C32: HW 설계검증 | D32: Discrete | E32: HW | F32: Proto~P1 | H32: =INDEX(가정!$C$7:$L$9,MATCH(가정!$C$4,가정!$B$7:$B$9,0),MATCH(E32,가정!$C$6:$L$6,0))*(I32/SUMIF($E$5:$E$33,E32,$I$5:$I$33)) -> 0.015 | I32: =COUNTIF(WP_상세!$B$5:$B$500,B32) -> 6 | J32: =IFERROR(ROUND(AVERAGEIF(WP_상세!$B$5:$B$500,B32,WP_상세!$L$5:$L$500)*100,1),0) -> 62.5 | K32: A/B 샘플 개발 등 HW 병행개발 존재를 가정하여 실질 비중 배정
A33: 29 | B33: HWE.4 | C33: HW 요구사항검증 | D33: Discrete | E33: HW | F33: P1~P2 | H33: =INDEX(가정!$C$7:$L$9,MATCH(가정!$C$4,가정!$B$7:$B$9,0),MATCH(E33,가정!$C$6:$L$6,0))*(I33/SUMIF($E$5:$E$33,E33,$I$5:$I$33)) -> 0.015 | I33: =COUNTIF(WP_상세!$B$5:$B$500,B33) -> 6 | J33: =IFERROR(ROUND(AVERAGEIF(WP_상세!$B$5:$B$500,B33,WP_상세!$L$5:$L$500)*100,1),0) -> 12.5 | K33: A/B 샘플 개발 등 HW 병행개발 존재를 가정하여 실질 비중 배정
G35: 합계(=100 확인) | H35: =SUM(H5:H33) -> 1

Sheet WP_상세
A4: No | B4: Process(CA) | C4: CA명 | D4: SW계층 | E4: BP# | F4: WP명(산출물) | G4: 목표 마일스톤 | H4: 관리방식(확정) | I4: 유지보수반영 | J4: 최초작성비중(%) | K4: 채점기준 연계 | L4: 진도율(%) | M4: 상태 | N4: 수기검토 비고 | O4: 근거자료
A5: 1 | B5: ACQ.4 | C5: 협약/공급자 모니터링 | E5: 1 | F5: Commitment/Agreement / 공급자 관리 합의서/협약서 | G5: M-Car | H5: Discrete | I5: N | J5: 1 | K5: 자가평가워크북 [M-Car] 시트 BP#1 동일 | L5: 1 | M5: 완료
A6: 2 | B6: ACQ.4 | C6: 협약/공급자 모니터링 | E6: 2 | F6: Communication Evidence / 공급자 교신/커뮤니케이션 증적 | G6: Proto | H6: Discrete | I6: N | J6: 1 | K6: 자가평가워크북 [Proto] 시트 BP#2 동일 | L6: 1 | M6: 완료
A7: 3 | B7: ACQ.4 | C7: 협약/공급자 모니터링 | E7: 3 | F7: Review Evidence / 개발 작업산출물 공동검토 기록 | G7: Proto | H7: LOE | K7: 자가평가워크북 [Proto] 시트 BP#3 동일 | L7: 1 | M7: 완료 | N7: 자동제안 Discrete → 수기검토 LOE
A8: 4 | B8: ACQ.4 | C8: 협약/공급자 모니터링 | E8: 4 | F8: Progress Status / 공급자 진척현황 보고서 | G8: Proto | H8: LOE | K8: 자가평가워크북 [Proto] 시트 BP#4 동일 | L8: 1 | M8: 완료
A9: 5 | B9: ACQ.4 | C9: 협약/공급자 모니터링 | E9: 5 | F9: Corrective Action / 시정조치 기록서 | G9: P1 | H9: LOE | K9: 자가평가워크북 [P1] 시트 BP#5 동일 | L9: 0.25 | M9: 진행중 | N9: 자동제안 Discrete → 수기검토 LOE
A10: 6 | B10: SPL.2 | C10: 제품 릴리스 관리 | E10: 1 | F10: Product Release Criteria / 릴리스 기능내용/기준 정의서 | G10: 릴리즈이력 참조 | H10: Discrete | K10: 자가평가워크북 [릴리즈이력 참조] 시트 BP#1 동일 | L10: 1 | M10: 완료
A11: 7 | B11: SPL.2 | C11: 제품 릴리스 관리 | E11: 2 | F11: Product Release Criteria / 릴리스 패키지 정의서 | G11: 릴리즈이력 참조 | H11: Discrete | K11: 자가평가워크북 [릴리즈이력 참조] 시트 BP#2 동일 | L11: 1 | M11: 완료
A12: 8 | B12: SPL.2 | C12: 제품 릴리스 관리 | E12: 3 | F12: Release Note / 릴리스 고유식별/번호체계 문서(릴리스 노트 내 포함) | G12: 릴리즈이력 참조 | H12: Discrete | K12: 자가평가워크북 [릴리즈이력 참조] 시트 BP#3 동일 | L12: 1 | M12: 완료
A13: 9 | B13: SPL.2 | C13: 제품 릴리스 관리 | E13: 4 | F13: Product Release Package / 릴리스 패키지(형상통제 항목 기반 빌드) | G13: 릴리즈이력 참조 | H13: Discrete | K13: 자가평가워크북 [릴리즈이력 참조] 시트 BP#4 동일 | L13: 0.6 | M13: 검토중
A14: 10 | B14: SPL.2 | C14: 제품 릴리스 관리 | E14: 5 | F14: Product Release Approval / 릴리스 승인서 | G14: 릴리즈이력 참조 | H14: Discrete | K14: 자가평가워크북 [릴리즈이력 참조] 시트 BP#5 동일 | L14: 0.6 | M14: 검토중
A15: 11 | B15: SPL.2 | C15: 제품 릴리스 관리 | E15: 6 | F15: Release Note / 릴리스 노트 | G15: 릴리즈이력 참조 | H15: Discrete | K15: 자가평가워크북 [릴리즈이력 참조] 시트 BP#6 동일 | L15: 0.6 | M15: 검토중
A16: 12 | B16: SPL.2 | C16: 제품 릴리스 관리 | E16: 7 | F16: Release Note / 릴리스 지원유형/수준/기간 안내서(릴리스 노트 내 포함) | G16: 릴리즈이력 참조 | H16: Discrete | K16: 자가평가워크북 [릴리즈이력 참조] 시트 BP#7 동일 | L16: 0.6 | M16: 검토중
A17: 13 | B17: SPL.2 | C17: 제품 릴리스 관리 | E17: 8 | F17: Delivery Evidence / 릴리스 패키지 인도/납품 증적 | G17: 릴리즈이력 참조 | H17: Discrete | K17: 자가평가워크북 [릴리즈이력 참조] 시트 BP#8 동일 | L17: 0.6 | M17: 검토중
A18: 14 | B18: MAN.3 | C18: 프로젝트 관리 | E18: 1 | F18: Project Plan / 프로젝트 작업범위 정의서(프로젝트 계획서 내 포함) | G18: M-Car | H18: Discrete | I18: Y | J18: 0.4 | K18: 자가평가워크북 [M-Car] 시트 BP#1 동일 | L18: 1 | M18: 완료
A19: 15 | B19: MAN.3 | C19: 프로젝트 관리 | E19: 2 | F19: Project Plan / 프로젝트 생명주기 정의서(프로젝트 계획서 내 포함) | G19: M-Car | H19: Discrete | I19: Y | J19: 0.4 | K19: 자가평가워크북 [M-Car] 시트 BP#2 동일 | L19: 1 | M19: 완료
A20: 16 | B20: MAN.3 | C20: 프로젝트 관리 | E20: 3 | F20: Analysis Results / 프로젝트 실현가능성 분석서 | G20: M-Car | H20: Discrete | I20: N | J20: 1 | K20: 자가평가워크북 [M-Car] 시트 BP#3 동일 | L20: 1 | M20: 완료
A21: 17 | B21: MAN.3 | C21: 프로젝트 관리 | E21: 4 | F21: Project Plan / 작업패키지/WBS 정의서(프로젝트 계획서 내 포함) | G21: M-Car | H21: Discrete | I21: Y | J21: 0.4 | K21: 자가평가워크북 [M-Car] 시트 BP#4 동일 | L21: 1 | M21: 완료
A22: 18 | B22: MAN.3 | C22: 프로젝트 관리 | E22: 5 | F22: Project Plan / 프로젝트 산정치 및 자원계획서(프로젝트 계획서 내 포함) | G22: M-Car | H22: Discrete | I22: Y | J22: 0.4 | K22: 자가평가워크북 [M-Car] 시트 BP#5 동일 | L22: 1 | M22: 완료
A23: 19 | B23: MAN.3 | C23: 프로젝트 관리 | E23: 6 | F23: Project Plan / 필요 기술/지식/경험(역량) 계획서(프로젝트 계획서 내 포함) | G23: M-Car | H23: Discrete | I23: Y | J23: 0.4 | K23: 자가평가워크북 [M-Car] 시트 BP#6 동일 | L23: 1 | M23: 완료
A24: 20 | B24: MAN.3 | C24: 프로젝트 관리 | E24: 7 | F24: Project Plan / 프로젝트 인터페이스 및 합의된 약속사항 정의서(프로젝트 계획서 내 포함) | G24: M-Car | H24: Discrete | I24: Y | J24: 0.4 | K24: 자가평가워크북 [M-Car] 시트 BP#7 동일 | L24: 1 | M24: 완료
A25: 21 | B25: MAN.3 | C25: 프로젝트 관리 | E25: 8 | F25: Project Plan / 프로젝트 일정표(프로젝트 계획서 내 포함) | G25: M-Car | H25: Discrete | I25: Y | J25: 0.4 | K25: 자가평가워크북 [M-Car] 시트 BP#8 동일 | L25: 1 | M25: 완료
A26: 22 | B26: MAN.3 | C26: 프로젝트 관리 | E26: 9 | F26: Consistency Evidence / 프로젝트 계획 일관성 검증 근거 | G26: P1 | H26: Discrete | I26: N | J26: 1 | K26: 자가평가워크북 [P1] 시트 BP#9 동일 | L26: 0.25 | M26: 진행중
A27: 23 | B27: MAN.3 | C27: 프로젝트 관리 | E27: 10 | F27: Progress Status / 프로젝트 진척현황 보고서 | G27: P1 | H27: LOE | K27: 자가평가워크북 [P1] 시트 BP#10 동일 | L27: 0.25 | M27: 진행중
A28: 24 | B28: SUP.1 | C28: 품질보증(QA) | E28: 1 | F28: Quality Assurance Plan / 품질보증 독립성 명시 문서(품질보증계획서 내 포함) | G28: M-Car | H28: Discrete | I28: Y | J28: 0.4 | K28: 자가평가워크북 [M-Car] 시트 BP#1 동일 | L28: 1 | M28: 완료
A29: 25 | B29: SUP.1 | C29: 품질보증(QA) | E29: 2 | F29: Quality Assurance Plan / 품질보증 기준/체크리스트(품질보증계획서 내 포함) | G29: M-Car | H29: Discrete | I29: Y | J29: 0.4 | K29: 자가평가워크북 [M-Car] 시트 BP#2 동일 | L29: 1 | M29: 완료
A30: 26 | B30: SUP.1 | C30: 품질보증(QA) | E30: 3 | F30: Review Evidence / 작업산출물 품질검토 기록 | G30: Proto | H30: LOE | K30: 자가평가워크북 [Proto] 시트 BP#3 동일 | L30: 1 | M30: 완료
A31: 27 | B31: SUP.1 | C31: 품질보증(QA) | E31: 4 | F31: Audit Report / 프로세스 활동 품질감사 보고서 | G31: Proto | H31: Discrete | I31: N | J31: 1 | K31: 자가평가워크북 [Proto] 시트 BP#4 동일 | L31: 1 | M31: 완료
A32: 28 | B32: SUP.1 | C32: 품질보증(QA) | E32: 5 | F32: Communication Evidence / 품질보증 활동/결과 요약보고서 | G32: P1 | H32: LOE | K32: 자가평가워크북 [P1] 시트 BP#5 동일 | L32: 0.25 | M32: 진행중
A33: 29 | B33: SUP.1 | C33: 품질보증(QA) | E33: 6 | F33: Corrective Action / 부적합사항 시정조치 기록 | G33: P1 | H33: LOE | K33: 자가평가워크북 [P1] 시트 BP#6 동일 | L33: 0.25 | M33: 진행중
A34: 30 | B34: SUP.1 | C34: 품질보증(QA) | E34: 7 | F34: Corrective Action / 부적합사항 에스컬레이션(상위보고) 기록 | G34: P1 | H34: LOE | K34: 자가평가워크북 [P1] 시트 BP#7 동일 | L34: 0.25 | M34: 진행중
A35: 31 | B35: SUP.8 | C35: 형상관리(CM) | E35: 1 | F35: Configuration Item List / 형상항목 식별목록 | G35: M-Car | H35: Discrete | I35: N | J35: 1 | K35: 자가평가워크북 [M-Car] 시트 BP#1 동일 | L35: 1 | M35: 완료
A36: 32 | B36: SUP.8 | C36: 형상관리(CM) | E36: 2 | F36: Configuration Item List / 형상항목 속성정의서 | G36: M-Car | H36: Discrete | I36: N | J36: 1 | K36: 자가평가워크북 [M-Car] 시트 BP#2 동일 | L36: 1 | M36: 완료
A37: 33 | B37: SUP.8 | C37: 형상관리(CM) | E37: 3 | F37: Configuration Management Plan / 형상관리계획서 | G37: M-Car | H37: Discrete | I37: Y | J37: 0.4 | K37: 자가평가워크북 [M-Car] 시트 BP#3 동일 | L37: 1 | M37: 완료
A38: 34 | B38: SUP.8 | C38: 형상관리(CM) | E38: 4 | F38: Change Request / 형상항목 변경통제 기록 | G38: Proto | H38: LOE | K38: 자가평가워크북 [Proto] 시트 BP#4 동일 | L38: 1 | M38: 완료
A39: 35 | B39: SUP.8 | C39: 형상관리(CM) | E39: 5 | F39: Baseline / 베이스라인 기록서 | G39: Proto | H39: Discrete | I39: N | J39: 1 | K39: 자가평가워크북 [Proto] 시트 BP#5 동일 | L39: 1 | M39: 완료
A40: 36 | B40: SUP.8 | C40: 형상관리(CM) | E40: 6 | F40: Communication Evidence / 형상현황 요약/공유 보고서 | G40: P1 | H40: LOE | K40: 자가평가워크북 [P1] 시트 BP#6 동일 | L40: 0.25 | M40: 진행중
A41: 37 | B41: SUP.8 | C41: 형상관리(CM) | E41: 7 | F41: Consistency Evidence / 형상항목 완전성/일관성 검증 기록 | G41: P1 | H41: Discrete | I41: N | J41: 1 | K41: 자가평가워크북 [P1] 시트 BP#7 동일 | L41: 0.25 | M41: 진행중
A42: 38 | B42: SUP.8 | C42: 형상관리(CM) | E42: 8 | F42: Verification Results / 백업 및 복구 메커니즘 가용성 검증 기록 | G42: P1 | H42: Discrete | I42: N | J42: 1 | K42: 자가평가워크북 [P1] 시트 BP#8 동일 | L42: 0.25 | M42: 진행중
A43: 39 | B43: SUP.9 | C43: 문제해결관리 | E43: 1 | F43: Problem Record / 문제 식별/기록서 | G43: Proto | H43: LOE | K43: 자가평가워크북 [Proto] 시트 BP#1 동일 | L43: 1 | M43: 완료
...

Sheet 마일스톤_요약
A4: 마일스톤 | B4: Discrete WP 수 | C4: LOE WP 수 | D4: 합계 | E4: 비중(%) | F4: 원본 비중(Discrete만, 비교기준) | G4: 보정후 가중치 | H4: 보정후 비중(%) | I4: 차이(비중, %p) | J4: 사유(왜 원본과 다른가)
A5: M-Car | B5: =COUNTIFS(WP_상세!$G$5:$G$500,A5,WP_상세!$H$5:$H$500,"Discrete") -> 63 | C5: =COUNTIFS(WP_상세!$G$5:$G$500,A5,WP_상세!$H$5:$H$500,"LOE") -> 0 | D5: =B5+C5 -> 63 | E5: =IF($D$11=0,0,D5/$D$11) -> 0.36 | F5: =IFERROR(B5/SUM($B$5:$B$9),0) -> 0.43448276 | G5: =계획곡선_보정!H184 -> 48.12 | H5: =IFERROR(G5/$G$13,0) -> 0.33186207 | I5: =H5-F5 -> -0.10262069 | J5: 요구사항·아키텍처 등 설계/계획형 산출물은 여기서 '최초 작성'되지만 이후 마일스톤까지 계속 개정된다. 최초작성분(가정: 40%)만 이 시점에 남고, 나머지 60%는 후속 마일스톤으로 재배분되어 원본 대비 비중이 낮아짐(WP_상세 '유지보수반영=Y' 대상).
A6: Proto | B6: =COUNTIFS(WP_상세!$G$5:$G$500,A6,WP_상세!$H$5:$H$500,"Discrete") -> 35 | C6: =COUNTIFS(WP_상세!$G$5:$G$500,A6,WP_상세!$H$5:$H$500,"LOE") -> 11 | D6: =B6+C6 -> 46 | E6: =IF($D$11=0,0,D6/$D$11) -> 0.26285714 | F6: =IFERROR(B6/SUM($B$5:$B$9),0) -> 0.24137931 | G6: =계획곡선_보정!I184 -> 36.02 | H6: =IFERROR(G6/$G$13,0) -> 0.24841379 | I6: =H6-F6 -> 0.0070344828 | J6: M-Car에서 시작된 지속개정형 산출물의 유지보수 개정분 일부가 이 마일스톤에 추가 배분되어 원본보다 비중이 소폭 상승.
A7: P1 | B7: =COUNTIFS(WP_상세!$G$5:$G$500,A7,WP_상세!$H$5:$H$500,"Discrete") -> 29 | C7: =COUNTIFS(WP_상세!$G$5:$G$500,A7,WP_상세!$H$5:$H$500,"LOE") -> 11 | D7: =B7+C7 -> 40 | E7: =IF($D$11=0,0,D7/$D$11) -> 0.22857143 | F7: =IFERROR(B7/SUM($B$5:$B$9),0) -> 0.2 | G7: =계획곡선_보정!J184 -> 33.62 | H7: =IFERROR(G7/$G$13,0) -> 0.23186207 | I7: =H7-F7 -> 0.031862069 | J7: 동일한 유지보수 개정분 배분 효과로 원본보다 비중 상승.
A8: P2 | B8: =COUNTIFS(WP_상세!$G$5:$G$500,A8,WP_상세!$H$5:$H$500,"Discrete") -> 18 | C8: =COUNTIFS(WP_상세!$G$5:$G$500,A8,WP_상세!$H$5:$H$500,"LOE") -> 0 | D8: =B8+C8 -> 18 | E8: =IF($D$11=0,0,D8/$D$11) -> 0.10285714 | F8: =IFERROR(B8/SUM($B$5:$B$9),0) -> 0.12413793 | G8: =계획곡선_보정!K184 -> 22.62 | H8: =IFERROR(G8/$G$13,0) -> 0.156 | I8: =H8-F8 -> 0.031862069 | J8: 동일한 유지보수 개정분 배분 효과로 원본보다 비중 상승.
A9: SoP | B9: =COUNTIFS(WP_상세!$G$5:$G$500,A9,WP_상세!$H$5:$H$500,"Discrete") -> 0 | C9: =COUNTIFS(WP_상세!$G$5:$G$500,A9,WP_상세!$H$5:$H$500,"LOE") -> 0 | D9: =B9+C9 -> 0 | E9: =IF($D$11=0,0,D9/$D$11) -> 0 | F9: =IFERROR(B9/SUM($B$5:$B$9),0) -> 0 | G9: =계획곡선_보정!L184 -> 4.62 | H9: =IFERROR(G9/$G$13,0) -> 0.031862069 | I9: =H9-F9 -> 0.031862069 | J9: 원본은 신규 산출물이 없어 0%였으나, M-Car~P2에서 시작된 산출물들의 유지보수 개정이 프로젝트 종료 시점까지 이어진다고 가정해 배분되므로 0%가 아닌 값을 갖게 됨.
A10: 릴리즈이력 참조 | B10: =COUNTIFS(WP_상세!$G$5:$G$500,A10,WP_상세!$H$5:$H$500,"Discrete") -> 8 | C10: =COUNTIFS(WP_상세!$G$5:$G$500,A10,WP_상세!$H$5:$H$500,"LOE") -> 0 | D10: =B10+C10 -> 8 | E10: =IF($D$11=0,0,D10/$D$11) -> 0.045714286 | F10: 해당없음 | G10: 해당없음 | H10: 해당없음 | I10: 해당없음 | J10: 별도 트랙(배포 이벤트)이라 유지보수 개정 보정 대상에서 제외(설계문서 8장 참조).
A11: 합계 | B11: =SUM(B5:B10) -> 153 | C11: =SUM(C5:C10) -> 22 | D11: =SUM(D5:D10) -> 175
A13: 보정후 전체 합계(참고) | G13: =계획곡선_보정!H184+계획곡선_보정!I184+계획곡선_보정!J184+계획곡선_보정!K184+계획곡선_보정!L184 -> 145
A15: ※ '보정후'는 계획곡선_보정 시트(11~12장, 유지보수 개정 반영)의 결과를 그대로 가져온 것이다. 두 표가 다르게 보이는 것은 오류가 아니라, 설계/계획형 산출물이 원 마일스톤 이후에도 계속 개정된다는 사실을 반영했기 때문이다.

Sheet LOE_계정
A4: LOE 계정명 | B4: 성격 | C4: 관리 방식 | D4: 월별 계획(PV) 방식 | E4: 담당(CAM) | F4: 비고
A5: 프로젝트 공통비(공통경비) | B5: LOE | C5: 비배부 — 별도 CA로 집계(설계문서 7장 방식 A) | D5: 월 정액 균등분할 | F5: PM/CM/QA 등 특정 CA에 배부하지 않음
A6: 출장경비 | B6: LOE(경비 풀) | C6: 프로젝트 공통비 CA에 합산 관리 | D6: 월별 계획 대비 실비 비교 | F6: MM이 아닌 순수 경비이므로 별도 관리
A7: PM 정기활동(회의체 운영 등) | B7: LOE | C7: MAN.3 CA 내 LOE WP로 관리(설계문서 6-3) | D7: 시간비례 | F7: 계획서 승인 등 이벤트성 활동은 WP_상세의 Discrete WP로 별도 관리

Sheet 가정
B4: ① 개발 시나리오 선택 | C4: 균형자체개발형(ASW-BSW 유사비중) | D4: ← 이 셀의 드롭다운에서 프로젝트 상황에 맞는 시나리오를 선택하면 CA_개요의 BAC 배분비중이 자동으로 바뀝니다.
B6: 시나리오\카테고리 | C6: 관리/LOE | D6: 릴리스 | E6: 조달 | F6: 시스템 | G6: 공통(SW설계) | H6: ASW | I6: BSW | J6: 통합 | K6: HW | L6: 검증 | M6: 합계(=100% 확인)
B7: 균형자체개발형(ASW-BSW 유사비중) | C7: 0.18 | D7: 0.04 | E7: 0.08 | F7: 0.08 | G7: 0.06 | H7: 0.22 | I7: 0.2 | J7: 0.06 | K7: 0.06 | L7: 0.02 | M7: =SUM(C7:L7) -> 1
B8: 완성차 ASW사급+BSW전량외주(당사 통합중심) | C8: 0.14 | D8: 0.03 | E8: 0.18 | F8: 0.05 | G8: 0.03 | H8: 0.03 | I8: 0.45 | J8: 0.07 | K8: 0.02 | L8: 0 | M8: =SUM(C8:L8) -> 1
B9: Tier-1 표준형(ASW자체개발, BSW외주/AUTOSAR구매) | C9: 0.18 | D9: 0.04 | E9: 0.1 | F9: 0.07 | G9: 0.05 | H9: 0.32 | I9: 0.08 | J9: 0.08 | K9: 0.06 | L9: 0.02 | M9: =SUM(C9:L9) -> 1
B11: 시나리오 설명
B12: 균형자체개발형(ASW-BSW 유사비중) | C12: ASW/BSW를 모두 자체 인력으로 개발하며 두 계층의 비중이 비슷한 경우
B13: 완성차 ASW사급+BSW전량외주(당사 통합중심) | C13: 완성차가 ASW를 사급하고 BSW는 전량 외주, 당사는 통합·검증 위주로 수행하는 경우
B14: Tier-1 표준형(ASW자체개발, BSW외주/AUTOSAR구매) | C14: ASW는 자체개발(ML 포함)하고 BSW는 외주 또는 AUTOSAR 상용툴 구매로 조달하는 일반적 구조
B18: ② 그 외 가정 목록
B19: ML 처리 방식 가정 | C19: ML(머신러닝)은 별도 관리체계를 두지 않고 ASW의 일부로 취급. SUP.11(ML데이터관리), MLE.1~4 CA는 원본 자가평가 워크북 구조를 보존하기 위해 CA 자체는 남기되, BAC 카테고리는 모두 'ASW'로 배정.
B20: HW 병행개발 가정 | C20: A/B 샘플 개발 등 HW가 SW와 함께 병행 개발된다고 가정하여 HWE.1~4를 'HW' 카테고리로 배정, 3개 시나리오 모두에서 2~6% 실질 비중을 부여함(이전 초안의 '해당없음 0%'에서 변경).
B21: ASW/BSW CA 분리 | C21: SWE.3(상세설계/단위구현), SWE.4(단위검증)는 계층별로 담당(자체 vs 외주)이 크게 달라지는 지점이므로 'SWE.3-ASW/BSW', 'SWE.4-ASW/BSW' 4개 CA로 분리. 원본 자가평가 워크북은 계층 구분 없이 BP를 채점하므로, 이 4개 CA는 동일한 BP#/채점기준을 공유하되 진도율은 계층별로 각자 입력해야 함(자가평가 워크북 자체의 계층 확장은 별도 검토 필요).
B22: 개발 시나리오 매트릭스 | C22: 외주 구조(ASW 자체개발/BSW 외주, 완성차 사급 등)에 따라 카테고리 목표비중이 크게 달라지므로, 고정값 대신 3가지 시나리오를 매트릭스로 제공하고 C4셀에서 선택하도록 구성. 제시된 3개 시나리오는 예시이며, 실제 계약구조가 다르면 매트릭스의 숫자를 직접 수정(노란색 셀)하거나 새 행을 추가해도 됨.
B23: CA 내 BAC 세부 배분 방식 | C23: 각 카테고리 목표비중을, CA_개요의 '소속 WP(산출물) 개수'에 비례하여 같은 카테고리 내 CA들에 배분(=목표비중×해당CA WP수/해당카테고리 전체WP수). 실제 MM 계획이 수립되면 이 근사 배분을 교체할 것(설계문서 5장: BAC는 궁극적으로 실제 MM 계획 기반이어야 함).
B24: 혼합 CA의 Discrete/LOE 최종 확정 | C24: WP_상세의 관리방식(확정) 열은 산출물명 키워드 자동제안에 수기검토를 거쳐 확정한 것. ACQ.4 BP3(공동검토기록), BP5(시정조치기록)는 반복적 활동 성격이 강해 자동제안(Discrete)에서 LOE로 재분류함(K열에 표시). 나머지 혼합 CA(SUP.1/SUP.8/SUP.10)는 자동제안값을 그대로 채택.
B25: 마일스톤 정규화 시점 가정 | C25: 계획곡선 산정을 위해 프로젝트 전체 기간 대비 마일스톤 시점을 M-Car=15%, Proto=40%, P1=60%, P2=85%, SoP=100%로 가정(자동차 SW 개발의 전형적 마일스톤 간격 기준). 실제 프로젝트 일정표가 확정되면 반드시 교체할 것.
B26: 계획곡선의 성격에 대한 유의사항 | C26: 계획곡선_후보 시트의 후보A/B는 마일스톤별 'Discrete WP 개수'의 누적 비율을 기반으로 산정한 것으로, 실제 공수(effort) 가중치가 아닌 산출물 개수 기준의 1차 근사치임. 산출물이 초반 마일스톤(M-Car)에 다수 몰려 있어(요구사항·아키텍처 산출물 집중) 전형적인 대칭 S자보다 초반에 급격히 상승하는 형태로 나타남.
B27: 유지보수 개정 보정(중요) | C27: SW 산출물은 원 마일스톤에서 생성된 뒤 끝나는 것이 아니라 프로젝트 종료 시점까지 지속적으로 개정된다(요구사항 변경, 아키텍처 refinement, 코드 수정 등). 이를 반영하기 위해 '계획곡선_보정' 시트를 추가: 설계/계획형 산출물(Requirement/Architecture/Design/Project Plan/Software Unit 등, WP_상세의 '유지보수반영=Y')은 BAC의 40%를 원 마일스톤에 '최초작성'으로, 나머지 60%를 원 마일스톤부터 SoP까지 잔여 마일스톤에 균등 배분하여 '유지보수 개정'으로 인식. 이 보정을 반영하면 M-Car 비중이 46%→33%로 낮아지고 마일스톤 간 분포가 훨씬 평평해져, 투입인력이 초반에 구성되어 끝까지 유지되는 실제 패턴과 더 부합함. 계획곡선_후보의 '후보 C'가 이 보정을 반영한 베타곡선(α≈0.74, β≈1.41)이며 현재 권장안임. 40%/60% 분할비율 자체도 가정이므로 실적 축적 후 조정 필요(WP_상세의 '최초작성비중(%)' 열에서 개별 조정 가능).
B30: ③ 실적MM/월별 계획 가정
B31: 총 프로젝트 기간(개월) | C31: 12 | D31: 가정 — 실제 프로젝트 일정표 확정 시 교체
B32: 총 투입 규모(MM) | C32: 100 | D32: 가정(라운드넘버 placeholder) — 실제 인력계획(요원별 투입기간) 수립 시 교체
B33: 월별 계획MM 배분 방식 | C33: 균등배분 | D33: 사용자가 언급한 대로 인력이 프로젝트 초반 구성 후 종료까지 유지되는 패턴을 반영해, CA별 총계획MM을 전체 개월 수에 균등 배분(1차 근사). 정교화 시 계획곡선_보정의 마일스톤별 가중치를 월 단위로 환산해 대체 가능.
B34: ACWP-BCWP 독립성 원칙 | D34: 실적MM_입력 시트는 진도율과 무관하게 CAM이 실제 투입한 공수만 입력. EVMS_대시보드에서 WP_상세 진도율(BCWP)과 결합해 SPI/CPI 산출(설계문서 5장 원칙).
B35: ④ 자가평가 워크북 계층 확장 가정
B36: 원본 워크북 미변경 원칙 | D36: 원본 ASpice_selfAssessment_perMilestones_v1.xlsm은 매크로(VBA) 기반 자동재생성 구조라 임의 구조변경 시 매크로가 깨질 위험이 있어 직접 수정하지 않음. 대신 본 워크북에 'SWE34_계층별_채점보충' 시트를 신설해 SWE.3/SWE.4의 BP를 ASW/BSW 계층별로 각자 채점하도록 함. 원본 워크북의 채점기준표(계획수립10/작성40/동료검토20/보고승인20/PM체크10, 등급S~D)를 그대로 복제해 사용.
B37: 향후 정식 확장 필요 | D37: 이 보충 시트는 임시방편이며, 장기적으로는 원본 워크북 자체에 계층(ASW/BSW) 차원을 정식 추가하는 것을 권장(1단계 숙제 항목은 아니었으나 2단계 수행 중 새로 식별된 후속 과제).
B39: ⑤ 노무단가 환산 가정 (MM ↔ 원화 통합)
B40: 노무단가(원/시간) | C40: 50000 | D40: 시간당 50,000원 가정. 이 셀 값을 바꾸면 EVMS_대시보드의 원화환산 전체가 자동 갱신됨.
B41: 1MM당 표준시간(시간) | C41: 160 | D41: 가정(20일×8시간). 실제 표준근로시간 정책에 맞춰 조정 가능(예: 209시간 등).
B42: 노무단가(원/MM, 자동계산) | C42: =C40*C41 -> 8000000 | D42: 노무단가(원/시간) × 1MM당 표준시간. EVMS_대시보드의 모든 원화환산 컬럼이 이 셀을 참조.
B43: 계획·실적 동일 단가 원칙 | D43: BCWS/BCWP(계획·성과)와 ACWP(실적) 환산에 동일한 노무단가를 적용한다. 단가 자체의 변동(임률 차이)은 모델링하지 않으므로, MM 기준 SPI/CPI와 원화 기준 SPI/CPI는 이론상 완전히 같은 값이 된다 — 원가 통합의 목적은 단가 차이 반영이 아니라 현금성 예산과 합산 가능한 공통 단위를 만드는 것이다.
B44: ⑥ 마일스톤 정규화 시점표 (BCWS 계단함수 계산용)
B45: 마일스톤 | C45: 정규화 시점(%)
B46: M-Car | C46: 0.15
B47: Proto | C47: 0.4
B48: P1 | C48: 0.6
B49: P2 | C49: 0.85
B50: SoP | C50: 1
D51: 11장·12장에서 계획곡선 산정에 쓰였던 가정을 여기 정식 셀로 옮겼다. 지금까지는 계산 스크립트 안에만 있던 숫자라 워크북에서 재사용할 수 없었다. 프로젝트예산_현금성의 BCWS 계산이 이 표를 참조한다. 실제 마일스톤 일정이 확정되면 이 표만 고치면 된다.

Sheet 계획곡선_후보
B4: 실측 기준점 (WP개수 누적비율, 마일스톤 시점은 가정)
B5: 마일스톤 | C5: 정규화 시점(t) | D5: 누적 Discrete WP | E5: 누적비율
B6: M-Car | C6: 0.15 | D6: 63 | E6: =D6/$D$10 -> 0.45985401
B7: Proto | C7: 0.4 | D7: 89 | E7: =D7/$D$10 -> 0.64963504
B8: P1 | C8: 0.6 | D8: 119 | E8: =D8/$D$10 -> 0.86861314
B9: P2 | C9: 0.85 | D9: 137 | E9: =D9/$D$10 -> 1
B10: SoP | C10: 1 | D10: 137 | E10: =D10/$D$10 -> 1
B12: 피팅 결과(최소자승)
B13: 후보 A - 산출물개수 실증근사(미보정) | C13: alpha= | D13: 0.527 | E13: beta= | F13: 1.349
B14: 후보 B - 전형적 대칭 S자(대안) | C14: alpha= | D14: 2 | E14: beta= | F14: 2
B15: 후보 C - 유지보수 개정 보정 반영(권장) | C15: alpha= | D15: 0.744 | E15: beta= | F15: 1.408
B17: t(정규화 시점) | C17: 후보A 누적% | D17: 후보B 누적% | E17: 후보C 누적%(권장)
B18: 0 | C18: =BETADIST(0,$D$13,$F$13) -> 0 | D18: =BETADIST(0,$D$14,$F$14) -> 0 | E18: =BETADIST(0,$D$15,$F$15) -> 0
B19: 0.05 | C19: =BETADIST(0.05,$D$13,$F$13) -> 0.24718941 | D19: =BETADIST(0.05,$D$14,$F$14) -> 0.00725 | E19: =BETADIST(0.05,$D$15,$F$15) -> 0.14082757
B20: 0.1 | C20: =BETADIST(0.1,$D$13,$F$13) -> 0.35395761 | D20: =BETADIST(0.1,$D$14,$F$14) -> 0.028 | E20: =BETADIST(0.1,$D$15,$F$15) -> 0.23372777
B21: 0.15 | C21: =BETADIST(0.15,$D$13,$F$13) -> 0.43546516 | D21: =BETADIST(0.15,$D$14,$F$14) -> 0.06075 | E21: =BETADIST(0.15,$D$15,$F$15) -> 0.31308322
B22: 0.2 | C22: =BETADIST(0.2,$D$13,$F$13) -> 0.50340342 | D22: =BETADIST(0.2,$D$14,$F$14) -> 0.104 | E22: =BETADIST(0.2,$D$15,$F$15) -> 0.38408236
B23: 0.25 | C23: =BETADIST(0.25,$D$13,$F$13) -> 0.56236666 | D23: =BETADIST(0.25,$D$14,$F$14) -> 0.15625 | E23: =BETADIST(0.25,$D$15,$F$15) -> 0.44895039
B24: 0.3 | C24: =BETADIST(0.3,$D$13,$F$13) -> 0.61473035 | D24: =BETADIST(0.3,$D$14,$F$14) -> 0.216 | E24: =BETADIST(0.3,$D$15,$F$15) -> 0.50890159
B25: 0.35 | C25: =BETADIST(0.35,$D$13,$F$13) -> 0.66190992 | D25: =BETADIST(0.35,$D$14,$F$14) -> 0.28175 | E25: =BETADIST(0.35,$D$15,$F$15) -> 0.56468443
B26: 0.4 | C26: =BETADIST(0.4,$D$13,$F$13) -> 0.70482504 | D26: =BETADIST(0.4,$D$14,$F$14) -> 0.352 | E26: =BETADIST(0.4,$D$15,$F$15) -> 0.61679341
B27: 0.45 | C27: =BETADIST(0.45,$D$13,$F$13) -> 0.74410799 | D27: =BETADIST(0.45,$D$14,$F$14) -> 0.42525 | E27: =BETADIST(0.45,$D$15,$F$15) -> 0.66556791
B28: 0.5 | C28: =BETADIST(0.5,$D$13,$F$13) -> 0.78020947 | D28: =BETADIST(0.5,$D$14,$F$14) -> 0.5 | E28: =BETADIST(0.5,$D$15,$F$15) -> 0.71124347
B29: 0.55 | C29: =BETADIST(0.55,$D$13,$F$13) -> 0.81345725 | D29: =BETADIST(0.55,$D$14,$F$14) -> 0.57475 | E29: =BETADIST(0.55,$D$15,$F$15) -> 0.75398028
B30: 0.6 | C30: =BETADIST(0.6,$D$13,$F$13) -> 0.84409011 | D30: =BETADIST(0.6,$D$14,$F$14) -> 0.648 | E30: =BETADIST(0.6,$D$15,$F$15) -> 0.79387905
B31: 0.65 | C31: =BETADIST(0.65,$D$13,$F$13) -> 0.87227784 | D31: =BETADIST(0.65,$D$14,$F$14) -> 0.71825 | E31: =BETADIST(0.65,$D$15,$F$15) -> 0.83098888
B32: 0.7 | C32: =BETADIST(0.7,$D$13,$F$13) -> 0.89813195 | D32: =BETADIST(0.7,$D$14,$F$14) -> 0.784 | E32: =BETADIST(0.7,$D$15,$F$15) -> 0.86530891
B33: 0.75 | C33: =BETADIST(0.75,$D$13,$F$13) -> 0.92170898 | D33: =BETADIST(0.75,$D$14,$F$14) -> 0.84375 | E33: =BETADIST(0.75,$D$15,$F$15) -> 0.89678358
B34: 0.8 | C34: =BETADIST(0.8,$D$13,$F$13) -> 0.94300555 | D34: =BETADIST(0.8,$D$14,$F$14) -> 0.896 | E34: =BETADIST(0.8,$D$15,$F$15) -> 0.92528858
B35: 0.85 | C35: =BETADIST(0.85,$D$13,$F$13) -> 0.96194004 | D35: =BETADIST(0.85,$D$14,$F$14) -> 0.93925 | E35: =BETADIST(0.85,$D$15,$F$15) -> 0.95059935
B36: 0.9 | C36: =BETADIST(0.9,$D$13,$F$13) -> 0.97830327 | D36: =BETADIST(0.9,$D$14,$F$14) -> 0.972 | E36: =BETADIST(0.9,$D$15,$F$15) -> 0.97231711
B37: 0.95 | C37: =BETADIST(0.95,$D$13,$F$13) -> 0.99160452 | D37: =BETADIST(0.95,$D$14,$F$14) -> 0.99275 | E37: =BETADIST(0.95,$D$15,$F$15) -> 0.98965051
B38: 1 | C38: =BETADIST(1,$D$13,$F$13) -> 1 | D38: =BETADIST(1,$D$14,$F$14) -> 1 | E38: =BETADIST(1,$D$15,$F$15) -> 1

Sheet 계획곡선_보정
A4: 마일스톤 순서 index (참조용) | B4: M-Car | C4: Proto | D4: P1 | E4: P2 | F4: SoP
B5: 1 | C5: 2 | D5: 3 | E5: 4 | F5: 5
A7: No | B7: CA | C7: WP명 | D7: 목표마일스톤 | E7: 관리방식 | F7: 유지보수 | G7: 최초작성% | H7: M-Car 가중치 | I7: Proto 가중치 | J7: P1 가중치 | K7: P2 가중치 | L7: SoP 가중치
A8: =WP_상세!A5 -> 1 | B8: =WP_상세!B5 -> ACQ.4 | C8: =WP_상세!F5 -> Commitment/Agreement / 공급자 관리 합의서/협약서 | D8: =WP_상세!G5 -> M-Car | E8: =WP_상세!H5 -> Discrete | F8: =WP_상세!I5 -> N | G8: =WP_상세!J5 -> 1 | H8: =IFERROR(IF($E8<>"Discrete",0,IF(1<MATCH($D8,$B$4:$F$4,0),0,IF($F8<>"Y",IF(1=MATCH($D8,$B$4:$F$4,0),1,0),IF(1=MATCH($D8,$B$4:$F$4,0),$G8+(1-$G8)/(5-MATCH($D8,$B$4:$F$4,0)+1),(1-$G8)/(5-MATCH($D8,$B$4:$F$4,0)+1))))),0) -> 1 | I8: =IFERROR(IF($E8<>"Discrete",0,IF(2<MATCH($D8,$B$4:$F$4,0),0,IF($F8<>"Y",IF(2=MATCH($D8,$B$4:$F$4,0),1,0),IF(2=MATCH($D8,$B$4:$F$4,0),$G8+(1-$G8)/(5-MATCH($D8,$B$4:$F$4,0)+1),(1-$G8)/(5-MATCH($D8,$B$4:$F$4,0)+1))))),0) -> 0 | J8: =IFERROR(IF($E8<>"Discrete",0,IF(3<MATCH($D8,$B$4:$F$4,0),0,IF($F8<>"Y",IF(3=MATCH($D8,$B$4:$F$4,0),1,0),IF(3=MATCH($D8,$B$4:$F$4,0),$G8+(1-$G8)/(5-MATCH($D8,$B$4:$F$4,0)+1),(1-$G8)/(5-MATCH($D8,$B$4:$F$4,0)+1))))),0) -> 0 | K8: =IFERROR(IF($E8<>"Discrete",0,IF(4<MATCH($D8,$B$4:$F$4,0),0,IF($F8<>"Y",IF(4=MATCH($D8,$B$4:$F$4,0),1,0),IF(4=MATCH($D8,$B$4:$F$4,0),$G8+(1-$G8)/(5-MATCH($D8,$B$4:$F$4,0)+1),(1-$G8)/(5-MATCH($D8,$B$4:$F$4,0)+1))))),0) -> 0 | L8: =IFERROR(IF($E8<>"Discrete",0,IF(5<MATCH($D8,$B$4:$F$4,0),0,IF($F8<>"Y",IF(5=MATCH($D8,$B$4:$F$4,0),1,0),IF(5=MATCH($D8,$B$4:$F$4,0),$G8+(1-$G8)/(5-MATCH($D8,$B$4:$F$4,0)+1),(1-$G8)/(5-MATCH($D8,$B$4:$F$4,0)+1))))),0) -> 0
A9: =WP_상세!A6 -> 2 | B9: =WP_상세!B6 -> ACQ.4 | C9: =WP_상세!F6 -> Communication Evidence / 공급자 교신/커뮤니케이션 증적 | D9: =WP_상세!G6 -> Proto | E9: =WP_상세!H6 -> Discrete | F9: =WP_상세!I6 -> N | G9: =WP_상세!J6 -> 1 | H9: =IFERROR(IF($E9<>"Discrete",0,IF(1<MATCH($D9,$B$4:$F$4,0),0,IF($F9<>"Y",IF(1=MATCH($D9,$B$4:$F$4,0),1,0),IF(1=MATCH($D9,$B$4:$F$4,0),$G9+(1-$G9)/(5-MATCH($D9,$B$4:$F$4,0)+1),(1-$G9)/(5-MATCH($D9,$B$4:$F$4,0)+1))))),0) -> 0 | I9: =IFERROR(IF($E9<>"Discrete",0,IF(2<MATCH($D9,$B$4:$F$4,0),0,IF($F9<>"Y",IF(2=MATCH($D9,$B$4:$F$4,0),1,0),IF(2=MATCH($D9,$B$4:$F$4,0),$G9+(1-$G9)/(5-MATCH($D9,$B$4:$F$4,0)+1),(1-$G9)/(5-MATCH($D9,$B$4:$F$4,0)+1))))),0) -> 1 | J9: =IFERROR(IF($E9<>"Discrete",0,IF(3<MATCH($D9,$B$4:$F$4,0),0,IF($F9<>"Y",IF(3=MATCH($D9,$B$4:$F$4,0),1,0),IF(3=MATCH($D9,$B$4:$F$4,0),$G9+(1-$G9)/(5-MATCH($D9,$B$4:$F$4,0)+1),(1-$G9)/(5-MATCH($D9,$B$4:$F$4,0)+1))))),0) -> 0 | K9: =IFERROR(IF($E9<>"Discrete",0,IF(4<MATCH($D9,$B$4:$F$4,0),0,IF($F9<>"Y",IF(4=MATCH($D9,$B$4:$F$4,0),1,0),IF(4=MATCH($D9,$B$4:$F$4,0),$G9+(1-$G9)/(5-MATCH($D9,$B$4:$F$4,0)+1),(1-$G9)/(5-MATCH($D9,$B$4:$F$4,0)+1))))),0) -> 0 | L9: =IFERROR(IF($E9<>"Discrete",0,IF(5<MATCH($D9,$B$4:$F$4,0),0,IF($F9<>"Y",IF(5=MATCH($D9,$B$4:$F$4,0),1,0),IF(5=MATCH($D9,$B$4:$F$4,0),$G9+(1-$G9)/(5-MATCH($D9,$B$4:$F$4,0)+1),(1-$G9)/(5-MATCH($D9,$B$4:$F$4,0)+1))))),0) -> 0
A10: =WP_상세!A7 -> 3 | B10: =WP_상세!B7 -> ACQ.4 | C10: =WP_상세!F7 -> Review Evidence / 개발 작업산출물 공동검토 기록 | D10: =WP_상세!G7 -> Proto | E10: =WP_상세!H7 -> LOE | F10: =WP_상세!I7 -> 0 | G10: =WP_상세!J7 -> 0 | H10: =IFERROR(IF($E10<>"Discrete",0,IF(1<MATCH($D10,$B$4:$F$4,0),0,IF($F10<>"Y",IF(1=MATCH($D10,$B$4:$F$4,0),1,0),IF(1=MATCH($D10,$B$4:$F$4,0),$G10+(1-$G10)/(5-MATCH($D10,$B$4:$F$4,0)+1),(1-$G10)/(5-MATCH($D10,$B$4:$F$4,0)+1))))),0) -> 0 | I10: =IFERROR(IF($E10<>"Discrete",0,IF(2<MATCH($D10,$B$4:$F$4,0),0,IF($F10<>"Y",IF(2=MATCH($D10,$B$4:$F$4,0),1,0),IF(2=MATCH($D10,$B$4:$F$4,0),$G10+(1-$G10)/(5-MATCH($D10,$B$4:$F$4,0)+1),(1-$G10)/(5-MATCH($D10,$B$4:$F$4,0)+1))))),0) -> 0 | J10: =IFERROR(IF($E10<>"Discrete",0,IF(3<MATCH($D10,$B$4:$F$4,0),0,IF($F10<>"Y",IF(3=MATCH($D10,$B$4:$F$4,0),1,0),IF(3=MATCH($D10,$B$4:$F$4,0),$G10+(1-$G10)/(5-MATCH($D10,$B$4:$F$4,0)+1),(1-$G10)/(5-MATCH($D10,$B$4:$F$4,0)+1))))),0) -> 0 | K10: =IFERROR(IF($E10<>"Discrete",0,IF(4<MATCH($D10,$B$4:$F$4,0),0,IF($F10<>"Y",IF(4=MATCH($D10,$B$4:$F$4,0),1,0),IF(4=MATCH($D10,$B$4:$F$4,0),$G10+(1-$G10)/(5-MATCH($D10,$B$4:$F$4,0)+1),(1-$G10)/(5-MATCH($D10,$B$4:$F$4,0)+1))))),0) -> 0 | L10: =IFERROR(IF($E10<>"Discrete",0,IF(5<MATCH($D10,$B$4:$F$4,0),0,IF($F10<>"Y",IF(5=MATCH($D10,$B$4:$F$4,0),1,0),IF(5=MATCH($D10,$B$4:$F$4,0),$G10+(1-$G10)/(5-MATCH($D10,$B$4:$F$4,0)+1),(1-$G10)/(5-MATCH($D10,$B$4:$F$4,0)+1))))),0) -> 0
A11: =WP_상세!A8 -> 4 | B11: =WP_상세!B8 -> ACQ.4 | C11: =WP_상세!F8 -> Progress Status / 공급자 진척현황 보고서 | D11: =WP_상세!G8 -> Proto | E11: =WP_상세!H8 -> LOE | F11: =WP_상세!I8 -> 0 | G11: =WP_상세!J8 -> 0 | H11: =IFERROR(IF($E11<>"Discrete",0,IF(1<MATCH($D11,$B$4:$F$4,0),0,IF($F11<>"Y",IF(1=MATCH($D11,$B$4:$F$4,0),1,0),IF(1=MATCH($D11,$B$4:$F$4,0),$G11+(1-$G11)/(5-MATCH($D11,$B$4:$F$4,0)+1),(1-$G11)/(5-MATCH($D11,$B$4:$F$4,0)+1))))),0) -> 0 | I11: =IFERROR(IF($E11<>"Discrete",0,IF(2<MATCH($D11,$B$4:$F$4,0),0,IF($F11<>"Y",IF(2=MATCH($D11,$B$4:$F$4,0),1,0),IF(2=MATCH($D11,$B$4:$F$4,0),$G11+(1-$G11)/(5-MATCH($D11,$B$4:$F$4,0)+1),(1-$G11)/(5-MATCH($D11,$B$4:$F$4,0)+1))))),0) -> 0 | J11: =IFERROR(IF($E11<>"Discrete",0,IF(3<MATCH($D11,$B$4:$F$4,0),0,IF($F11<>"Y",IF(3=MATCH($D11,$B$4:$F$4,0),1,0),IF(3=MATCH($D11,$B$4:$F$4,0),$G11+(1-$G11)/(5-MATCH($D11,$B$4:$F$4,0)+1),(1-$G11)/(5-MATCH($D11,$B$4:$F$4,0)+1))))),0) -> 0 | K11: =IFERROR(IF($E11<>"Discrete",0,IF(4<MATCH($D11,$B$4:$F$4,0),0,IF($F11<>"Y",IF(4=MATCH($D11,$B$4:$F$4,0),1,0),IF(4=MATCH($D11,$B$4:$F$4,0),$G11+(1-$G11)/(5-MATCH($D11,$B$4:$F$4,0)+1),(1-$G11)/(5-MATCH($D11,$B$4:$F$4,0)+1))))),0) -> 0 | L11: =IFERROR(IF($E11<>"Discrete",0,IF(5<MATCH($D11,$B$4:$F$4,0),0,IF($F11<>"Y",IF(5=MATCH($D11,$B$4:$F$4,0),1,0),IF(5=MATCH($D11,$B$4:$F$4,0),$G11+(1-$G11)/(5-MATCH($D11,$B$4:$F$4,0)+1),(1-$G11)/(5-MATCH($D11,$B$4:$F$4,0)+1))))),0) -> 0
A12: =WP_상세!A9 -> 5 | B12: =WP_상세!B9 -> ACQ.4 | C12: =WP_상세!F9 -> Corrective Action / 시정조치 기록서 | D12: =WP_상세!G9 -> P1 | E12: =WP_상세!H9 -> LOE | F12: =WP_상세!I9 -> 0 | G12: =WP_상세!J9 -> 0 | H12: =IFERROR(IF($E12<>"Discrete",0,IF(1<MATCH($D12,$B$4:$F$4,0),0,IF($F12<>"Y",IF(1=MATCH($D12,$B$4:$F$4,0),1,0),IF(1=MATCH($D12,$B$4:$F$4,0),$G12+(1-$G12)/(5-MATCH($D12,$B$4:$F$4,0)+1),(1-$G12)/(5-MATCH($D12,$B$4:$F$4,0)+1))))),0) -> 0 | I12: =IFERROR(IF($E12<>"Discrete",0,IF(2<MATCH($D12,$B$4:$F$4,0),0,IF($F12<>"Y",IF(2=MATCH($D12,$B$4:$F$4,0),1,0),IF(2=MATCH($D12,$B$4:$F$4,0),$G12+(1-$G12)/(5-MATCH($D12,$B$4:$F$4,0)+1),(1-$G12)/(5-MATCH($D12,$B$4:$F$4,0)+1))))),0) -> 0 | J12: =IFERROR(IF($E12<>"Discrete",0,IF(3<MATCH($D12,$B$4:$F$4,0),0,IF($F12<>"Y",IF(3=MATCH($D12,$B$4:$F$4,0),1,0),IF(3=MATCH($D12,$B$4:$F$4,0),$G12+(1-$G12)/(5-MATCH($D12,$B$4:$F$4,0)+1),(1-$G12)/(5-MATCH($D12,$B$4:$F$4,0)+1))))),0) -> 0 | K12: =IFERROR(IF($E12<>"Discrete",0,IF(4<MATCH($D12,$B$4:$F$4,0),0,IF($F12<>"Y",IF(4=MATCH($D12,$B$4:$F$4,0),1,0),IF(4=MATCH($D12,$B$4:$F$4,0),$G12+(1-$G12)/(5-MATCH($D12,$B$4:$F$4,0)+1),(1-$G12)/(5-MATCH($D12,$B$4:$F$4,0)+1))))),0) -> 0 | L12: =IFERROR(IF($E12<>"Discrete",0,IF(5<MATCH($D12,$B$4:$F$4,0),0,IF($F12<>"Y",IF(5=MATCH($D12,$B$4:$F$4,0),1,0),IF(5=MATCH($D12,$B$4:$F$4,0),$G12+(1-$G12)/(5-MATCH($D12,$B$4:$F$4,0)+1),(1-$G12)/(5-MATCH($D12,$B$4:$F$4,0)+1))))),0) -> 0
A13: =WP_상세!A10 -> 6 | B13: =WP_상세!B10 -> SPL.2 | C13: =WP_상세!F10 -> Product Release Criteria / 릴리스 기능내용/기준 정의서 | D13: =WP_상세!G10 -> 릴리즈이력 참조 | E13: =WP_상세!H10 -> Discrete | F13: =WP_상세!I10 -> 0 | G13: =WP_상세!J10 -> 0 | H13: =IFERROR(IF($E13<>"Discrete",0,IF(1<MATCH($D13,$B$4:$F$4,0),0,IF($F13<>"Y",IF(1=MATCH($D13,$B$4:$F$4,0),1,0),IF(1=MATCH($D13,$B$4:$F$4,0),$G13+(1-$G13)/(5-MATCH($D13,$B$4:$F$4,0)+1),(1-$G13)/(5-MATCH($D13,$B$4:$F$4,0)+1))))),0) -> 0 | I13: =IFERROR(IF($E13<>"Discrete",0,IF(2<MATCH($D13,$B$4:$F$4,0),0,IF($F13<>"Y",IF(2=MATCH($D13,$B$4:$F$4,0),1,0),IF(2=MATCH($D13,$B$4:$F$4,0),$G13+(1-$G13)/(5-MATCH($D13,$B$4:$F$4,0)+1),(1-$G13)/(5-MATCH($D13,$B$4:$F$4,0)+1))))),0) -> 0 | J13: =IFERROR(IF($E13<>"Discrete",0,IF(3<MATCH($D13,$B$4:$F$4,0),0,IF($F13<>"Y",IF(3=MATCH($D13,$B$4:$F$4,0),1,0),IF(3=MATCH($D13,$B$4:$F$4,0),$G13+(1-$G13)/(5-MATCH($D13,$B$4:$F$4,0)+1),(1-$G13)/(5-MATCH($D13,$B$4:$F$4,0)+1))))),0) -> 0 | K13: =IFERROR(IF($E13<>"Discrete",0,IF(4<MATCH($D13,$B$4:$F$4,0),0,IF($F13<>"Y",IF(4=MATCH($D13,$B$4:$F$4,0),1,0),IF(4=MATCH($D13,$B$4:$F$4,0),$G13+(1-$G13)/(5-MATCH($D13,$B$4:$F$4,0)+1),(1-$G13)/(5-MATCH($D13,$B$4:$F$4,0)+1))))),0) -> 0 | L13: =IFERROR(IF($E13<>"Discrete",0,IF(5<MATCH($D13,$B$4:$F$4,0),0,IF($F13<>"Y",IF(5=MATCH($D13,$B$4:$F$4,0),1,0),IF(5=MATCH($D13,$B$4:$F$4,0),$G13+(1-$G13)/(5-MATCH($D13,$B$4:$F$4,0)+1),(1-$G13)/(5-MATCH($D13,$B$4:$F$4,0)+1))))),0) -> 0
A14: =WP_상세!A11 -> 7 | B14: =WP_상세!B11 -> SPL.2 | C14: =WP_상세!F11 -> Product Release Criteria / 릴리스 패키지 정의서 | D14: =WP_상세!G11 -> 릴리즈이력 참조 | E14: =WP_상세!H11 -> Discrete | F14: =WP_상세!I11 -> 0 | G14: =WP_상세!J11 -> 0 | H14: =IFERROR(IF($E14<>"Discrete",0,IF(1<MATCH($D14,$B$4:$F$4,0),0,IF($F14<>"Y",IF(1=MATCH($D14,$B$4:$F$4,0),1,0),IF(1=MATCH($D14,$B$4:$F$4,0),$G14+(1-$G14)/(5-MATCH($D14,$B$4:$F$4,0)+1),(1-$G14)/(5-MATCH($D14,$B$4:$F$4,0)+1))))),0) -> 0 | I14: =IFERROR(IF($E14<>"Discrete",0,IF(2<MATCH($D14,$B$4:$F$4,0),0,IF($F14<>"Y",IF(2=MATCH($D14,$B$4:$F$4,0),1,0),IF(2=MATCH($D14,$B$4:$F$4,0),$G14+(1-$G14)/(5-MATCH($D14,$B$4:$F$4,0)+1),(1-$G14)/(5-MATCH($D14,$B$4:$F$4,0)+1))))),0) -> 0 | J14: =IFERROR(IF($E14<>"Discrete",0,IF(3<MATCH($D14,$B$4:$F$4,0),0,IF($F14<>"Y",IF(3=MATCH($D14,$B$4:$F$4,0),1,0),IF(3=MATCH($D14,$B$4:$F$4,0),$G14+(1-$G14)/(5-MATCH($D14,$B$4:$F$4,0)+1),(1-$G14)/(5-MATCH($D14,$B$4:$F$4,0)+1))))),0) -> 0 | K14: =IFERROR(IF($E14<>"Discrete",0,IF(4<MATCH($D14,$B$4:$F$4,0),0,IF($F14<>"Y",IF(4=MATCH($D14,$B$4:$F$4,0),1,0),IF(4=MATCH($D14,$B$4:$F$4,0),$G14+(1-$G14)/(5-MATCH($D14,$B$4:$F$4,0)+1),(1-$G14)/(5-MATCH($D14,$B$4:$F$4,0)+1))))),0) -> 0 | L14: =IFERROR(IF($E14<>"Discrete",0,IF(5<MATCH($D14,$B$4:$F$4,0),0,IF($F14<>"Y",IF(5=MATCH($D14,$B$4:$F$4,0),1,0),IF(5=MATCH($D14,$B$4:$F$4,0),$G14+(1-$G14)/(5-MATCH($D14,$B$4:$F$4,0)+1),(1-$G14)/(5-MATCH($D14,$B$4:$F$4,0)+1))))),0) -> 0
A15: =WP_상세!A12 -> 8 | B15: =WP_상세!B12 -> SPL.2 | C15: =WP_상세!F12 -> Release Note / 릴리스 고유식별/번호체계 문서(릴리스 노트 내 포함) | D15: =WP_상세!G12 -> 릴리즈이력 참조 | E15: =WP_상세!H12 -> Discrete | F15: =WP_상세!I12 -> 0 | G15: =WP_상세!J12 -> 0 | H15: =IFERROR(IF($E15<>"Discrete",0,IF(1<MATCH($D15,$B$4:$F$4,0),0,IF($F15<>"Y",IF(1=MATCH($D15,$B$4:$F$4,0),1,0),IF(1=MATCH($D15,$B$4:$F$4,0),$G15+(1-$G15)/(5-MATCH($D15,$B$4:$F$4,0)+1),(1-$G15)/(5-MATCH($D15,$B$4:$F$4,0)+1))))),0) -> 0 | I15: =IFERROR(IF($E15<>"Discrete",0,IF(2<MATCH($D15,$B$4:$F$4,0),0,IF($F15<>"Y",IF(2=MATCH($D15,$B$4:$F$4,0),1,0),IF(2=MATCH($D15,$B$4:$F$4,0),$G15+(1-$G15)/(5-MATCH($D15,$B$4:$F$4,0)+1),(1-$G15)/(5-MATCH($D15,$B$4:$F$4,0)+1))))),0) -> 0 | J15: =IFERROR(IF($E15<>"Discrete",0,IF(3<MATCH($D15,$B$4:$F$4,0),0,IF($F15<>"Y",IF(3=MATCH($D15,$B$4:$F$4,0),1,0),IF(3=MATCH($D15,$B$4:$F$4,0),$G15+(1-$G15)/(5-MATCH($D15,$B$4:$F$4,0)+1),(1-$G15)/(5-MATCH($D15,$B$4:$F$4,0)+1))))),0) -> 0 | K15: =IFERROR(IF($E15<>"Discrete",0,IF(4<MATCH($D15,$B$4:$F$4,0),0,IF($F15<>"Y",IF(4=MATCH($D15,$B$4:$F$4,0),1,0),IF(4=MATCH($D15,$B$4:$F$4,0),$G15+(1-$G15)/(5-MATCH($D15,$B$4:$F$4,0)+1),(1-$G15)/(5-MATCH($D15,$B$4:$F$4,0)+1))))),0) -> 0 | L15: =IFERROR(IF($E15<>"Discrete",0,IF(5<MATCH($D15,$B$4:$F$4,0),0,IF($F15<>"Y",IF(5=MATCH($D15,$B$4:$F$4,0),1,0),IF(5=MATCH($D15,$B$4:$F$4,0),$G15+(1-$G15)/(5-MATCH($D15,$B$4:$F$4,0)+1),(1-$G15)/(5-MATCH($D15,$B$4:$F$4,0)+1))))),0) -> 0
A16: =WP_상세!A13 -> 9 | B16: =WP_상세!B13 -> SPL.2 | C16: =WP_상세!F13 -> Product Release Package / 릴리스 패키지(형상통제 항목 기반 빌드) | D16: =WP_상세!G13 -> 릴리즈이력 참조 | E16: =WP_상세!H13 -> Discrete | F16: =WP_상세!I13 -> 0 | G16: =WP_상세!J13 -> 0 | H16: =IFERROR(IF($E16<>"Discrete",0,IF(1<MATCH($D16,$B$4:$F$4,0),0,IF($F16<>"Y",IF(1=MATCH($D16,$B$4:$F$4,0),1,0),IF(1=MATCH($D16,$B$4:$F$4,0),$G16+(1-$G16)/(5-MATCH($D16,$B$4:$F$4,0)+1),(1-$G16)/(5-MATCH($D16,$B$4:$F$4,0)+1))))),0) -> 0 | I16: =IFERROR(IF($E16<>"Discrete",0,IF(2<MATCH($D16,$B$4:$F$4,0),0,IF($F16<>"Y",IF(2=MATCH($D16,$B$4:$F$4,0),1,0),IF(2=MATCH($D16,$B$4:$F$4,0),$G16+(1-$G16)/(5-MATCH($D16,$B$4:$F$4,0)+1),(1-$G16)/(5-MATCH($D16,$B$4:$F$4,0)+1))))),0) -> 0 | J16: =IFERROR(IF($E16<>"Discrete",0,IF(3<MATCH($D16,$B$4:$F$4,0),0,IF($F16<>"Y",IF(3=MATCH($D16,$B$4:$F$4,0),1,0),IF(3=MATCH($D16,$B$4:$F$4,0),$G16+(1-$G16)/(5-MATCH($D16,$B$4:$F$4,0)+1),(1-$G16)/(5-MATCH($D16,$B$4:$F$4,0)+1))))),0) -> 0 | K16: =IFERROR(IF($E16<>"Discrete",0,IF(4<MATCH($D16,$B$4:$F$4,0),0,IF($F16<>"Y",IF(4=MATCH($D16,$B$4:$F$4,0),1,0),IF(4=MATCH($D16,$B$4:$F$4,0),$G16+(1-$G16)/(5-MATCH($D16,$B$4:$F$4,0)+1),(1-$G16)/(5-MATCH($D16,$B$4:$F$4,0)+1))))),0) -> 0 | L16: =IFERROR(IF($E16<>"Discrete",0,IF(5<MATCH($D16,$B$4:$F$4,0),0,IF($F16<>"Y",IF(5=MATCH($D16,$B$4:$F$4,0),1,0),IF(5=MATCH($D16,$B$4:$F$4,0),$G16+(1-$G16)/(5-MATCH($D16,$B$4:$F$4,0)+1),(1-$G16)/(5-MATCH($D16,$B$4:$F$4,0)+1))))),0) -> 0
A17: =WP_상세!A14 -> 10 | B17: =WP_상세!B14 -> SPL.2 | C17: =WP_상세!F14 -> Product Release Approval / 릴리스 승인서 | D17: =WP_상세!G14 -> 릴리즈이력 참조 | E17: =WP_상세!H14 -> Discrete | F17: =WP_상세!I14 -> 0 | G17: =WP_상세!J14 -> 0 | H17: =IFERROR(IF($E17<>"Discrete",0,IF(1<MATCH($D17,$B$4:$F$4,0),0,IF($F17<>"Y",IF(1=MATCH($D17,$B$4:$F$4,0),1,0),IF(1=MATCH($D17,$B$4:$F$4,0),$G17+(1-$G17)/(5-MATCH($D17,$B$4:$F$4,0)+1),(1-$G17)/(5-MATCH($D17,$B$4:$F$4,0)+1))))),0) -> 0 | I17: =IFERROR(IF($E17<>"Discrete",0,IF(2<MATCH($D17,$B$4:$F$4,0),0,IF($F17<>"Y",IF(2=MATCH($D17,$B$4:$F$4,0),1,0),IF(2=MATCH($D17,$B$4:$F$4,0),$G17+(1-$G17)/(5-MATCH($D17,$B$4:$F$4,0)+1),(1-$G17)/(5-MATCH($D17,$B$4:$F$4,0)+1))))),0) -> 0 | J17: =IFERROR(IF($E17<>"Discrete",0,IF(3<MATCH($D17,$B$4:$F$4,0),0,IF($F17<>"Y",IF(3=MATCH($D17,$B$4:$F$4,0),1,0),IF(3=MATCH($D17,$B$4:$F$4,0),$G17+(1-$G17)/(5-MATCH($D17,$B$4:$F$4,0)+1),(1-$G17)/(5-MATCH($D17,$B$4:$F$4,0)+1))))),0) -> 0 | K17: =IFERROR(IF($E17<>"Discrete",0,IF(4<MATCH($D17,$B$4:$F$4,0),0,IF($F17<>"Y",IF(4=MATCH($D17,$B$4:$F$4,0),1,0),IF(4=MATCH($D17,$B$4:$F$4,0),$G17+(1-$G17)/(5-MATCH($D17,$B$4:$F$4,0)+1),(1-$G17)/(5-MATCH($D17,$B$4:$F$4,0)+1))))),0) -> 0 | L17: =IFERROR(IF($E17<>"Discrete",0,IF(5<MATCH($D17,$B$4:$F$4,0),0,IF($F17<>"Y",IF(5=MATCH($D17,$B$4:$F$4,0),1,0),IF(5=MATCH($D17,$B$4:$F$4,0),$G17+(1-$G17)/(5-MATCH($D17,$B$4:$F$4,0)+1),(1-$G17)/(5-MATCH($D17,$B$4:$F$4,0)+1))))),0) -> 0
A18: =WP_상세!A15 -> 11 | B18: =WP_상세!B15 -> SPL.2 | C18: =WP_상세!F15 -> Release Note / 릴리스 노트 | D18: =WP_상세!G15 -> 릴리즈이력 참조 | E18: =WP_상세!H15 -> Discrete | F18: =WP_상세!I15 -> 0 | G18: =WP_상세!J15 -> 0 | H18: =IFERROR(IF($E18<>"Discrete",0,IF(1<MATCH($D18,$B$4:$F$4,0),0,IF($F18<>"Y",IF(1=MATCH($D18,$B$4:$F$4,0),1,0),IF(1=MATCH($D18,$B$4:$F$4,0),$G18+(1-$G18)/(5-MATCH($D18,$B$4:$F$4,0)+1),(1-$G18)/(5-MATCH($D18,$B$4:$F$4,0)+1))))),0) -> 0 | I18: =IFERROR(IF($E18<>"Discrete",0,IF(2<MATCH($D18,$B$4:$F$4,0),0,IF($F18<>"Y",IF(2=MATCH($D18,$B$4:$F$4,0),1,0),IF(2=MATCH($D18,$B$4:$F$4,0),$G18+(1-$G18)/(5-MATCH($D18,$B$4:$F$4,0)+1),(1-$G18)/(5-MATCH($D18,$B$4:$F$4,0)+1))))),0) -> 0 | J18: =IFERROR(IF($E18<>"Discrete",0,IF(3<MATCH($D18,$B$4:$F$4,0),0,IF($F18<>"Y",IF(3=MATCH($D18,$B$4:$F$4,0),1,0),IF(3=MATCH($D18,$B$4:$F$4,0),$G18+(1-$G18)/(5-MATCH($D18,$B$4:$F$4,0)+1),(1-$G18)/(5-MATCH($D18,$B$4:$F$4,0)+1))))),0) -> 0 | K18: =IFERROR(IF($E18<>"Discrete",0,IF(4<MATCH($D18,$B$4:$F$4,0),0,IF($F18<>"Y",IF(4=MATCH($D18,$B$4:$F$4,0),1,0),IF(4=MATCH($D18,$B$4:$F$4,0),$G18+(1-$G18)/(5-MATCH($D18,$B$4:$F$4,0)+1),(1-$G18)/(5-MATCH($D18,$B$4:$F$4,0)+1))))),0) -> 0 | L18: =IFERROR(IF($E18<>"Discrete",0,IF(5<MATCH($D18,$B$4:$F$4,0),0,IF($F18<>"Y",IF(5=MATCH($D18,$B$4:$F$4,0),1,0),IF(5=MATCH($D18,$B$4:$F$4,0),$G18+(1-$G18)/(5-MATCH($D18,$B$4:$F$4,0)+1),(1-$G18)/(5-MATCH($D18,$B$4:$F$4,0)+1))))),0) -> 0
